Workbook
Name _30_abr_10: #REF!
Name ad: [1]!AnalystSheetClose
Name AE: [1]!AnalystSheetClose
Name ana: #REF!
Name auto_close: [2]!AnalystSheetClose
Name d: #REF!
Name desp_data: [3]BASE_METAXREAL!$Q:$Q
Name desp_meta: [3]BASE_METAXREAL!$P:$P
Name desp_real: [3]BASE_METAXREAL!$O:$O
Name Resumo_Saldo_Disponível: #REF!
Name Tabela: OFFSET([4]BD!$A$6,0,0,COUNTA([4]BD!$A:$A),COUNTA([4]BD!$6:$6))
Name Tipo_VGV: [3]VGV!$D$29:$D$221
Name Tipo_VGV: [3]VGV!$D$29:$D$221
Name Tipo_VGV: VGV!$D$29:$D$221
Name VGV: [3]VGV!$E$29:$E$221
Name VGV: [3]VGV!$E$29:$E$221
Name VGV: VGV!$E$29:$E$221
Name vgv_data: [3]VGV!$C$29:$C$221
Name vgv_data: [3]VGV!$C$29:$C$221
Name vgv_data: VGV!$C$29:$C$221
Name vgv_regional: [3]VGV!$A$29:$A$221
Name vgv_regional: [3]VGV!$A$29:$A$221
Name vgv_regional: VGV!$A$29:$A$221

Sheet VGV
C1: JANEIRO | E1: FEVEREIRO | G1: MARÇO | I1: ABRIL | K1: MAIO | M1: JUNHO | O1: JULHO | Q1: AGOSTO | S1: SETEMBRO | U1: OUTUBRO | W1: NOVEMBRO | Y1: DEZEMBRO | AA1: YTD | AC1: MÊS ATUAL
A2: ATUALIZAR VGV REAL | ÚLTIMO MÊS | B2: Regional | C2: VGV META | D2: VGV REAL | E2: VGV META | F2: VGV REAL | G2: VGV META | H2: VGV REAL | I2: VGV META | J2: VGV REAL | K2: VGV META | L2: VGV REAL | M2: VGV META | N2: VGV REAL | O2: VGV META | P2: VGV REAL | Q2: VGV META | R2: VGV REAL | S2: VGV META | T2: VGV REAL | U2: VGV META | V2: VGV REAL | W2: VGV META | X2: VGV REAL | Y2: VGV META | Z2: VGV REAL | AA2: VGV META | AB2: VGV REAL | AC2: VGV META | AD2: VGV REAL
B3: SP INT 1 | C3: =SUMIFS(orçvgv!$C:$C,orçvgv!$B:$B,VGV!$B3,orçvgv!$D:$D,C$13) -> 23751104 | D3: =SUMIFS('det_prop vgv'!$C:$C,'det_prop vgv'!$A:$A,VGV!$B3,'det_prop vgv'!$D:$D,D$13) -> 13731140 | E3: =SUMIFS(orçvgv!$C:$C,orçvgv!$B:$B,VGV!$B3,orçvgv!$D:$D,E$13) -> 17563656 | F3: =SUMIFS('det_prop vgv'!$C:$C,'det_prop vgv'!$A:$A,VGV!$B3,'det_prop vgv'!$D:$D,F$13) -> 13370126 | G3: =SUMIFS(orçvgv!$C:$C,orçvgv!$B:$B,VGV!$B3,orçvgv!$D:$D,G$13) -> 29271341 | H3: =SUMIFS('det_prop vgv'!$C:$C,'det_prop vgv'!$A:$A,VGV!$B3,'det_prop vgv'!$D:$D,H$13) -> 26703858 | I3: =SUMIFS(orçvgv!$C:$C,orçvgv!$B:$B,VGV!$B3,orçvgv!$D:$D,I$13) -> 23829009 | J3: =SUMIFS('det_prop vgv'!$C:$C,'det_prop vgv'!$A:$A,VGV!$B3,'det_prop vgv'!$D:$D,J$13) -> 26914386 | K3: =SUMIFS(orçvgv!$C:$C,orçvgv!$B:$B,VGV!$B3,orçvgv!$D:$D,K$13) -> 36770765 | L3: =SUMIFS('det_prop vgv'!$C:$C,'det_prop vgv'!$A:$A,VGV!$B3,'det_prop vgv'!$D:$D,L$13) -> 25715836 | M3: =SUMIFS(orçvgv!$C:$C,orçvgv!$B:$B,VGV!$B3,orçvgv!$D:$D,M$13) -> 42587968 | N3: =SUMIFS('det_prop vgv'!$C:$C,'det_prop vgv'!$A:$A,VGV!$B3,'det_prop vgv'!$D:$D,N$13) -> 57396495 | O3: =SUMIFS(orçvgv!$C:$C,orçvgv!$B:$B,VGV!$B3,orçvgv!$D:$D,O$13) -> 40330859 | P3: =SUMIFS('det_prop vgv'!$C:$C,'det_prop vgv'!$A:$A,VGV!$B3,'det_prop vgv'!$D:$D,P$13) -> 40336743 | Q3: =SUMIFS(orçvgv!$C:$C,orçvgv!$B:$B,VGV!$B3,orçvgv!$D:$D,Q$13) -> 32319060 | R3: =SUMIFS('det_prop vgv'!$C:$C,'det_prop vgv'!$A:$A,VGV!$B3,'det_prop vgv'!$D:$D,R$13) -> 30436130 | S3: =SUMIFS(orçvgv!$C:$C,orçvgv!$B:$B,VGV!$B3,orçvgv!$D:$D,S$13) -> 37520977 | T3: =SUMIFS('det_prop vgv'!$C:$C,'det_prop vgv'!$A:$A,VGV!$B3,'det_prop vgv'!$D:$D,T$13) -> 34006857 | U3: =SUMIFS(orçvgv!$C:$C,orçvgv!$B:$B,VGV!$B3,orçvgv!$D:$D,U$13) -> 56957385 | V3: =SUMIFS('det_prop vgv'!$C:$C,'det_prop vgv'!$A:$A,VGV!$B3,'det_prop vgv'!$D:$D,V$13) -> 0 | W3: =SUMIFS(orçvgv!$C:$C,orçvgv!$B:$B,VGV!$B3,orçvgv!$D:$D,W$13) -> 47138667 | X3: =SUMIFS('det_prop vgv'!$C:$C,'det_prop vgv'!$A:$A,VGV!$B3,'det_prop vgv'!$D:$D,X$13) -> 0 | Y3: =SUMIFS(orçvgv!$C:$C,orçvgv!$B:$B,VGV!$B3,orçvgv!$D:$D,Y$13) -> 43528767 | Z3: =SUMIFS('det_prop vgv'!$C:$C,'det_prop vgv'!$A:$A,VGV!$B3,'det_prop vgv'!$D:$D,Z$13) -> 0 | AA3: {=SUMIFS(E30:$E$221,B30:$B$221,$B$3:$B$10,C30:$C$221,"<="&$A$13,D30:$D$221,AA$2)} -> 2.4642376e+08 | AB3: {=SUMIFS($E30:F$221,$B30:C$221,$B$3:$B$10,$C30:D$221,"<="&$A$13,$D30:E$221,AB$2)} -> 2.3460471e+08 | AC3: {=IFERROR(INDEX($B$2:$Z$13,ROW($A$2:$A$10),MATCH(MONTH($A$13),$B$13:$Z$13,0)),0)} -> 32319060 | AD3: {=IFERROR(INDEX($B$2:$Z$13,ROW($A$2:$A$10),MATCH(MONTH($A$13),$B$13:$Z$13,0)+1),0)} -> 30436130
B4: SP INT 2 | C4: =SUMIFS(orçvgv!$C:$C,orçvgv!$B:$B,VGV!$B4,orçvgv!$D:$D,C$13) -> 32224838 | D4: =SUMIFS('det_prop vgv'!$C:$C,'det_prop vgv'!$A:$A,VGV!$B4,'det_prop vgv'!$D:$D,D$13) -> 20885139 | E4: =SUMIFS(orçvgv!$C:$C,orçvgv!$B:$B,VGV!$B4,orçvgv!$D:$D,E$13) -> 27602037 | F4: =SUMIFS('det_prop vgv'!$C:$C,'det_prop vgv'!$A:$A,VGV!$B4,'det_prop vgv'!$D:$D,F$13) -> 25158860 | G4: =SUMIFS(orçvgv!$C:$C,orçvgv!$B:$B,VGV!$B4,orçvgv!$D:$D,G$13) -> 28972158 | H4: =SUMIFS('det_prop vgv'!$C:$C,'det_prop vgv'!$A:$A,VGV!$B4,'det_prop vgv'!$D:$D,H$13) -> 69162230 | I4: =SUMIFS(orçvgv!$C:$C,orçvgv!$B:$B,VGV!$B4,orçvgv!$D:$D,I$13) -> 35804654 | J4: =SUMIFS('det_prop vgv'!$C:$C,'det_prop vgv'!$A:$A,VGV!$B4,'det_prop vgv'!$D:$D,J$13) -> 37993306 | K4: =SUMIFS(orçvgv!$C:$C,orçvgv!$B:$B,VGV!$B4,orçvgv!$D:$D,K$13) -> 33824246 | L4: =SUMIFS('det_prop vgv'!$C:$C,'det_prop vgv'!$A:$A,VGV!$B4,'det_prop vgv'!$D:$D,L$13) -> 33356471 | M4: =SUMIFS(orçvgv!$C:$C,orçvgv!$B:$B,VGV!$B4,orçvgv!$D:$D,M$13) -> 33584898 | N4: =SUMIFS('det_prop vgv'!$C:$C,'det_prop vgv'!$A:$A,VGV!$B4,'det_prop vgv'!$D:$D,N$13) -> 23301595 | O4: =SUMIFS(orçvgv!$C:$C,orçvgv!$B:$B,VGV!$B4,orçvgv!$D:$D,O$13) -> 31933826 | P4: =SUMIFS('det_prop vgv'!$C:$C,'det_prop vgv'!$A:$A,VGV!$B4,'det_prop vgv'!$D:$D,P$13) -> 17491530 | Q4: =SUMIFS(orçvgv!$C:$C,orçvgv!$B:$B,VGV!$B4,orçvgv!$D:$D,Q$13) -> 31307270 | R4: =SUMIFS('det_prop vgv'!$C:$C,'det_prop vgv'!$A:$A,VGV!$B4,'det_prop vgv'!$D:$D,R$13) -> 11656751 | S4: =SUMIFS(orçvgv!$C:$C,orçvgv!$B:$B,VGV!$B4,orçvgv!$D:$D,S$13) -> 30446291 | T4: =SUMIFS('det_prop vgv'!$C:$C,'det_prop vgv'!$A:$A,VGV!$B4,'det_prop vgv'!$D:$D,T$13) -> 20896872 | U4: =SUMIFS(orçvgv!$C:$C,orçvgv!$B:$B,VGV!$B4,orçvgv!$D:$D,U$13) -> 29062378 | V4: =SUMIFS('det_prop vgv'!$C:$C,'det_prop vgv'!$A:$A,VGV!$B4,'det_prop vgv'!$D:$D,V$13) -> 0 | W4: =SUMIFS(orçvgv!$C:$C,orçvgv!$B:$B,VGV!$B4,orçvgv!$D:$D,W$13) -> 28686617 | X4: =SUMIFS('det_prop vgv'!$C:$C,'det_prop vgv'!$A:$A,VGV!$B4,'det_prop vgv'!$D:$D,X$13) -> 0 | Y4: =SUMIFS(orçvgv!$C:$C,orçvgv!$B:$B,VGV!$B4,orçvgv!$D:$D,Y$13) -> 26819816 | Z4: =SUMIFS('det_prop vgv'!$C:$C,'det_prop vgv'!$A:$A,VGV!$B4,'det_prop vgv'!$D:$D,Z$13) -> 0 | AA4: 2.5525393e+08 | AB4: 2.3900588e+08 | AC4: 31307270 | AD4: 11656751
B5: SP INT 3 | C5: =SUMIFS(orçvgv!$C:$C,orçvgv!$B:$B,VGV!$B5,orçvgv!$D:$D,C$13) -> 24083418 | D5: =SUMIFS('det_prop vgv'!$C:$C,'det_prop vgv'!$A:$A,VGV!$B5,'det_prop vgv'!$D:$D,D$13) -> 23180208 | E5: =SUMIFS(orçvgv!$C:$C,orçvgv!$B:$B,VGV!$B5,orçvgv!$D:$D,E$13) -> 21774854 | F5: =SUMIFS('det_prop vgv'!$C:$C,'det_prop vgv'!$A:$A,VGV!$B5,'det_prop vgv'!$D:$D,F$13) -> 21409735 | G5: =SUMIFS(orçvgv!$C:$C,orçvgv!$B:$B,VGV!$B5,orçvgv!$D:$D,G$13) -> 25631321 | H5: =SUMIFS('det_prop vgv'!$C:$C,'det_prop vgv'!$A:$A,VGV!$B5,'det_prop vgv'!$D:$D,H$13) -> 32888520 | I5: =SUMIFS(orçvgv!$C:$C,orçvgv!$B:$B,VGV!$B5,orçvgv!$D:$D,I$13) -> 34973708 | J5: =SUMIFS('det_prop vgv'!$C:$C,'det_prop vgv'!$A:$A,VGV!$B5,'det_prop vgv'!$D:$D,J$13) -> 25842115 | K5: =SUMIFS(orçvgv!$C:$C,orçvgv!$B:$B,VGV!$B5,orçvgv!$D:$D,K$13) -> 31733884 | L5: =SUMIFS('det_prop vgv'!$C:$C,'det_prop vgv'!$A:$A,VGV!$B5,'det_prop vgv'!$D:$D,L$13) -> 25184073 | M5: =SUMIFS(orçvgv!$C:$C,orçvgv!$B:$B,VGV!$B5,orçvgv!$D:$D,M$13) -> 30595624 | N5: =SUMIFS('det_prop vgv'!$C:$C,'det_prop vgv'!$A:$A,VGV!$B5,'det_prop vgv'!$D:$D,N$13) -> 13486092 | O5: =SUMIFS(orçvgv!$C:$C,orçvgv!$B:$B,VGV!$B5,orçvgv!$D:$D,O$13) -> 27862238 | P5: =SUMIFS('det_prop vgv'!$C:$C,'det_prop vgv'!$A:$A,VGV!$B5,'det_prop vgv'!$D:$D,P$13) -> 20507963 | Q5: =SUMIFS(orçvgv!$C:$C,orçvgv!$B:$B,VGV!$B5,orçvgv!$D:$D,Q$13) -> 28113295 | R5: =SUMIFS('det_prop vgv'!$C:$C,'det_prop vgv'!$A:$A,VGV!$B5,'det_prop vgv'!$D:$D,R$13) -> 15838599 | S5: =SUMIFS(orçvgv!$C:$C,orçvgv!$B:$B,VGV!$B5,orçvgv!$D:$D,S$13) -> 42765437 | T5: =SUMIFS('det_prop vgv'!$C:$C,'det_prop vgv'!$A:$A,VGV!$B5,'det_prop vgv'!$D:$D,T$13) -> 25749692 | U5: =SUMIFS(orçvgv!$C:$C,orçvgv!$B:$B,VGV!$B5,orçvgv!$D:$D,U$13) -> 31392213 | V5: =SUMIFS('det_prop vgv'!$C:$C,'det_prop vgv'!$A:$A,VGV!$B5,'det_prop vgv'!$D:$D,V$13) -> 0 | W5: =SUMIFS(orçvgv!$C:$C,orçvgv!$B:$B,VGV!$B5,orçvgv!$D:$D,W$13) -> 29256322 | X5: =SUMIFS('det_prop vgv'!$C:$C,'det_prop vgv'!$A:$A,VGV!$B5,'det_prop vgv'!$D:$D,X$13) -> 0 | Y5: =SUMIFS(orçvgv!$C:$C,orçvgv!$B:$B,VGV!$B5,orçvgv!$D:$D,Y$13) -> 23747960 | Z5: =SUMIFS('det_prop vgv'!$C:$C,'det_prop vgv'!$A:$A,VGV!$B5,'det_prop vgv'!$D:$D,Z$13) -> 0 | AA5: 2.2476834e+08 | AB5: 1.7833731e+08 | AC5: 28113295 | AD5: 15838599 | AH5: GST. COM SPI 1 | AI5: GST. COM SPI 2 | AJ5: GST. COM SPI 3 | AK5: GST. COM SPI 4 | AL5: GST. COM SPI 5 | AM5: GST. COM SPI 6 | AN5: GST. VENDAS SENSIA CP | AO5: GST. VENDAS SENSIA RP
B6: SP INT 4 | C6: =SUMIFS(orçvgv!$C:$C,orçvgv!$B:$B,VGV!$B6,orçvgv!$D:$D,C$13) -> 19598621 | D6: =SUMIFS('det_prop vgv'!$C:$C,'det_prop vgv'!$A:$A,VGV!$B6,'det_prop vgv'!$D:$D,D$13) -> 19278104 | E6: =SUMIFS(orçvgv!$C:$C,orçvgv!$B:$B,VGV!$B6,orçvgv!$D:$D,E$13) -> 15363449 | F6: =SUMIFS('det_prop vgv'!$C:$C,'det_prop vgv'!$A:$A,VGV!$B6,'det_prop vgv'!$D:$D,F$13) -> 17895240 | G6: =SUMIFS(orçvgv!$C:$C,orçvgv!$B:$B,VGV!$B6,orçvgv!$D:$D,G$13) -> 26220121 | H6: =SUMIFS('det_prop vgv'!$C:$C,'det_prop vgv'!$A:$A,VGV!$B6,'det_prop vgv'!$D:$D,H$13) -> 26148600 | I6: =SUMIFS(orçvgv!$C:$C,orçvgv!$B:$B,VGV!$B6,orçvgv!$D:$D,I$13) -> 22348418 | J6: =SUMIFS('det_prop vgv'!$C:$C,'det_prop vgv'!$A:$A,VGV!$B6,'det_prop vgv'!$D:$D,J$13) -> 34088734 | K6: =SUMIFS(orçvgv!$C:$C,orçvgv!$B:$B,VGV!$B6,orçvgv!$D:$D,K$13) -> 20853291 | L6: =SUMIFS('det_prop vgv'!$C:$C,'det_prop vgv'!$A:$A,VGV!$B6,'det_prop vgv'!$D:$D,L$13) -> 27009924 | M6: =SUMIFS(orçvgv!$C:$C,orçvgv!$B:$B,VGV!$B6,orçvgv!$D:$D,M$13) -> 20993677 | N6: =SUMIFS('det_prop vgv'!$C:$C,'det_prop vgv'!$A:$A,VGV!$B6,'det_prop vgv'!$D:$D,N$13) -> 19964574 | O6: =SUMIFS(orçvgv!$C:$C,orçvgv!$B:$B,VGV!$B6,orçvgv!$D:$D,O$13) -> 20906890 | P6: =SUMIFS('det_prop vgv'!$C:$C,'det_prop vgv'!$A:$A,VGV!$B6,'det_prop vgv'!$D:$D,P$13) -> 16900101 | Q6: =SUMIFS(orçvgv!$C:$C,orçvgv!$B:$B,VGV!$B6,orçvgv!$D:$D,Q$13) -> 20827969 | R6: =SUMIFS('det_prop vgv'!$C:$C,'det_prop vgv'!$A:$A,VGV!$B6,'det_prop vgv'!$D:$D,R$13) -> 16328947 | S6: =SUMIFS(orçvgv!$C:$C,orçvgv!$B:$B,VGV!$B6,orçvgv!$D:$D,S$13) -> 21623394 | T6: =SUMIFS('det_prop vgv'!$C:$C,'det_prop vgv'!$A:$A,VGV!$B6,'det_prop vgv'!$D:$D,T$13) -> 15992108 | U6: =SUMIFS(orçvgv!$C:$C,orçvgv!$B:$B,VGV!$B6,orçvgv!$D:$D,U$13) -> 20161160 | V6: =SUMIFS('det_prop vgv'!$C:$C,'det_prop vgv'!$A:$A,VGV!$B6,'det_prop vgv'!$D:$D,V$13) -> 0 | W6: =SUMIFS(orçvgv!$C:$C,orçvgv!$B:$B,VGV!$B6,orçvgv!$D:$D,W$13) -> 20055529 | X6: =SUMIFS('det_prop vgv'!$C:$C,'det_prop vgv'!$A:$A,VGV!$B6,'det_prop vgv'!$D:$D,X$13) -> 0 | Y6: =SUMIFS(orçvgv!$C:$C,orçvgv!$B:$B,VGV!$B6,orçvgv!$D:$D,Y$13) -> 16942746 | Z6: =SUMIFS('det_prop vgv'!$C:$C,'det_prop vgv'!$A:$A,VGV!$B6,'det_prop vgv'!$D:$D,Z$13) -> 0 | AA6: 1.6711243e+08 | AB6: 1.7761422e+08 | AC6: 20827969 | AD6: 16328947
B7: SP INT 5 | C7: =SUMIFS(orçvgv!$C:$C,orçvgv!$B:$B,VGV!$B7,orçvgv!$D:$D,C$13) -> 21306681 | D7: =SUMIFS('det_prop vgv'!$C:$C,'det_prop vgv'!$A:$A,VGV!$B7,'det_prop vgv'!$D:$D,D$13) -> 16015426 | E7: =SUMIFS(orçvgv!$C:$C,orçvgv!$B:$B,VGV!$B7,orçvgv!$D:$D,E$13) -> 19382823 | F7: =SUMIFS('det_prop vgv'!$C:$C,'det_prop vgv'!$A:$A,VGV!$B7,'det_prop vgv'!$D:$D,F$13) -> 8968271.5 | G7: =SUMIFS(orçvgv!$C:$C,orçvgv!$B:$B,VGV!$B7,orçvgv!$D:$D,G$13) -> 21913974 | H7: =SUMIFS('det_prop vgv'!$C:$C,'det_prop vgv'!$A:$A,VGV!$B7,'det_prop vgv'!$D:$D,H$13) -> 11328714 | I7: =SUMIFS(orçvgv!$C:$C,orçvgv!$B:$B,VGV!$B7,orçvgv!$D:$D,I$13) -> 23370298 | J7: =SUMIFS('det_prop vgv'!$C:$C,'det_prop vgv'!$A:$A,VGV!$B7,'det_prop vgv'!$D:$D,J$13) -> 12825190 | K7: =SUMIFS(orçvgv!$C:$C,orçvgv!$B:$B,VGV!$B7,orçvgv!$D:$D,K$13) -> 22006064 | L7: =SUMIFS('det_prop vgv'!$C:$C,'det_prop vgv'!$A:$A,VGV!$B7,'det_prop vgv'!$D:$D,L$13) -> 14611716 | M7: =SUMIFS(orçvgv!$C:$C,orçvgv!$B:$B,VGV!$B7,orçvgv!$D:$D,M$13) -> 20034800 | N7: =SUMIFS('det_prop vgv'!$C:$C,'det_prop vgv'!$A:$A,VGV!$B7,'det_prop vgv'!$D:$D,N$13) -> 13562331 | O7: =SUMIFS(orçvgv!$C:$C,orçvgv!$B:$B,VGV!$B7,orçvgv!$D:$D,O$13) -> 20162905 | P7: =SUMIFS('det_prop vgv'!$C:$C,'det_prop vgv'!$A:$A,VGV!$B7,'det_prop vgv'!$D:$D,P$13) -> 10006407 | Q7: =SUMIFS(orçvgv!$C:$C,orçvgv!$B:$B,VGV!$B7,orçvgv!$D:$D,Q$13) -> 20076244 | R7: =SUMIFS('det_prop vgv'!$C:$C,'det_prop vgv'!$A:$A,VGV!$B7,'det_prop vgv'!$D:$D,R$13) -> 13776395 | S7: =SUMIFS(orçvgv!$C:$C,orçvgv!$B:$B,VGV!$B7,orçvgv!$D:$D,S$13) -> 20756004 | T7: =SUMIFS('det_prop vgv'!$C:$C,'det_prop vgv'!$A:$A,VGV!$B7,'det_prop vgv'!$D:$D,T$13) -> 25845085 | U7: =SUMIFS(orçvgv!$C:$C,orçvgv!$B:$B,VGV!$B7,orçvgv!$D:$D,U$13) -> 16862257 | V7: =SUMIFS('det_prop vgv'!$C:$C,'det_prop vgv'!$A:$A,VGV!$B7,'det_prop vgv'!$D:$D,V$13) -> 0 | W7: =SUMIFS(orçvgv!$C:$C,orçvgv!$B:$B,VGV!$B7,orçvgv!$D:$D,W$13) -> 17702564 | X7: =SUMIFS('det_prop vgv'!$C:$C,'det_prop vgv'!$A:$A,VGV!$B7,'det_prop vgv'!$D:$D,X$13) -> 0 | Y7: =SUMIFS(orçvgv!$C:$C,orçvgv!$B:$B,VGV!$B7,orçvgv!$D:$D,Y$13) -> 16132355 | Z7: =SUMIFS('det_prop vgv'!$C:$C,'det_prop vgv'!$A:$A,VGV!$B7,'det_prop vgv'!$D:$D,Z$13) -> 0 | AA7: 1.6825379e+08 | AB7: 1.0109445e+08 | AC7: 20076244 | AD7: 13776395
B8: SP INT 6 | C8: =SUMIFS(orçvgv!$C:$C,orçvgv!$B:$B,VGV!$B8,orçvgv!$D:$D,C$13) -> 21244756 | D8: =SUMIFS('det_prop vgv'!$C:$C,'det_prop vgv'!$A:$A,VGV!$B8,'det_prop vgv'!$D:$D,D$13) -> 13921999 | E8: =SUMIFS(orçvgv!$C:$C,orçvgv!$B:$B,VGV!$B8,orçvgv!$D:$D,E$13) -> 19325841 | F8: =SUMIFS('det_prop vgv'!$C:$C,'det_prop vgv'!$A:$A,VGV!$B8,'det_prop vgv'!$D:$D,F$13) -> 11823129 | G8: =SUMIFS(orçvgv!$C:$C,orçvgv!$B:$B,VGV!$B8,orçvgv!$D:$D,G$13) -> 29006058 | H8: =SUMIFS('det_prop vgv'!$C:$C,'det_prop vgv'!$A:$A,VGV!$B8,'det_prop vgv'!$D:$D,H$13) -> 18814562 | I8: =SUMIFS(orçvgv!$C:$C,orçvgv!$B:$B,VGV!$B8,orçvgv!$D:$D,I$13) -> 20960158 | J8: =SUMIFS('det_prop vgv'!$C:$C,'det_prop vgv'!$A:$A,VGV!$B8,'det_prop vgv'!$D:$D,J$13) -> 19020894 | K8: =SUMIFS(orçvgv!$C:$C,orçvgv!$B:$B,VGV!$B8,orçvgv!$D:$D,K$13) -> 21648084 | L8: =SUMIFS('det_prop vgv'!$C:$C,'det_prop vgv'!$A:$A,VGV!$B8,'det_prop vgv'!$D:$D,L$13) -> 17593150 | M8: =SUMIFS(orçvgv!$C:$C,orçvgv!$B:$B,VGV!$B8,orçvgv!$D:$D,M$13) -> 22524218 | N8: =SUMIFS('det_prop vgv'!$C:$C,'det_prop vgv'!$A:$A,VGV!$B8,'det_prop vgv'!$D:$D,N$13) -> 21430307 | O8: =SUMIFS(orçvgv!$C:$C,orçvgv!$B:$B,VGV!$B8,orçvgv!$D:$D,O$13) -> 22362906 | P8: =SUMIFS('det_prop vgv'!$C:$C,'det_prop vgv'!$A:$A,VGV!$B8,'det_prop vgv'!$D:$D,P$13) -> 16330738 | Q8: =SUMIFS(orçvgv!$C:$C,orçvgv!$B:$B,VGV!$B8,orçvgv!$D:$D,Q$13) -> 28688900 | R8: =SUMIFS('det_prop vgv'!$C:$C,'det_prop vgv'!$A:$A,VGV!$B8,'det_prop vgv'!$D:$D,R$13) -> 20606280 | S8: =SUMIFS(orçvgv!$C:$C,orçvgv!$B:$B,VGV!$B8,orçvgv!$D:$D,S$13) -> 32832746 | T8: =SUMIFS('det_prop vgv'!$C:$C,'det_prop vgv'!$A:$A,VGV!$B8,'det_prop vgv'!$D:$D,T$13) -> 29859663 | U8: =SUMIFS(orçvgv!$C:$C,orçvgv!$B:$B,VGV!$B8,orçvgv!$D:$D,U$13) -> 39267051 | V8: =SUMIFS('det_prop vgv'!$C:$C,'det_prop vgv'!$A:$A,VGV!$B8,'det_prop vgv'!$D:$D,V$13) -> 0 | W8: =SUMIFS(orçvgv!$C:$C,orçvgv!$B:$B,VGV!$B8,orçvgv!$D:$D,W$13) -> 32861421 | X8: =SUMIFS('det_prop vgv'!$C:$C,'det_prop vgv'!$A:$A,VGV!$B8,'det_prop vgv'!$D:$D,X$13) -> 0 | Y8: =SUMIFS(orçvgv!$C:$C,orçvgv!$B:$B,VGV!$B8,orçvgv!$D:$D,Y$13) -> 25134636 | Z8: =SUMIFS('det_prop vgv'!$C:$C,'det_prop vgv'!$A:$A,VGV!$B8,'det_prop vgv'!$D:$D,Z$13) -> 0 | AA8: 1.8576092e+08 | AB8: 1.3954106e+08 | AC8: 28688900 | AD8: 20606280
B9: SENSIA CP | C9: =SUMIFS(orçvgv!$C:$C,orçvgv!$B:$B,VGV!$B9,orçvgv!$D:$D,C$13) -> 8436050.2 | D9: =SUMIFS('det_prop vgv'!$C:$C,'det_prop vgv'!$A:$A,VGV!$B9,'det_prop vgv'!$D:$D,D$13) -> 6672794.8 | E9: =SUMIFS(orçvgv!$C:$C,orçvgv!$B:$B,VGV!$B9,orçvgv!$D:$D,E$13) -> 7034425.2 | F9: =SUMIFS('det_prop vgv'!$C:$C,'det_prop vgv'!$A:$A,VGV!$B9,'det_prop vgv'!$D:$D,F$13) -> 11592028 | G9: =SUMIFS(orçvgv!$C:$C,orçvgv!$B:$B,VGV!$B9,orçvgv!$D:$D,G$13) -> 7991380 | H9: =SUMIFS('det_prop vgv'!$C:$C,'det_prop vgv'!$A:$A,VGV!$B9,'det_prop vgv'!$D:$D,H$13) -> 14095749 | I9: =SUMIFS(orçvgv!$C:$C,orçvgv!$B:$B,VGV!$B9,orçvgv!$D:$D,I$13) -> 8043324 | J9: =SUMIFS('det_prop vgv'!$C:$C,'det_prop vgv'!$A:$A,VGV!$B9,'det_prop vgv'!$D:$D,J$13) -> 7008613.6 | K9: =SUMIFS(orçvgv!$C:$C,orçvgv!$B:$B,VGV!$B9,orçvgv!$D:$D,K$13) -> 8838128.2 | L9: =SUMIFS('det_prop vgv'!$C:$C,'det_prop vgv'!$A:$A,VGV!$B9,'det_prop vgv'!$D:$D,L$13) -> 18788579 | M9: =SUMIFS(orçvgv!$C:$C,orçvgv!$B:$B,VGV!$B9,orçvgv!$D:$D,M$13) -> 8895576 | N9: =SUMIFS('det_prop vgv'!$C:$C,'det_prop vgv'!$A:$A,VGV!$B9,'det_prop vgv'!$D:$D,N$13) -> 14435356 | O9: =SUMIFS(orçvgv!$C:$C,orçvgv!$B:$B,VGV!$B9,orçvgv!$D:$D,O$13) -> 8953397.3 | P9: =SUMIFS('det_prop vgv'!$C:$C,'det_prop vgv'!$A:$A,VGV!$B9,'det_prop vgv'!$D:$D,P$13) -> 15273188 | Q9: =SUMIFS(orçvgv!$C:$C,orçvgv!$B:$B,VGV!$B9,orçvgv!$D:$D,Q$13) -> 9114608 | R9: =SUMIFS('det_prop vgv'!$C:$C,'det_prop vgv'!$A:$A,VGV!$B9,'det_prop vgv'!$D:$D,R$13) -> 10295489 | S9: =SUMIFS(orçvgv!$C:$C,orçvgv!$B:$B,VGV!$B9,orçvgv!$D:$D,S$13) -> 9800614.4 | T9: =SUMIFS('det_prop vgv'!$C:$C,'det_prop vgv'!$A:$A,VGV!$B9,'det_prop vgv'!$D:$D,T$13) -> 12794802 | U9: =SUMIFS(orçvgv!$C:$C,orçvgv!$B:$B,VGV!$B9,orçvgv!$D:$D,U$13) -> 9233483 | V9: =SUMIFS('det_prop vgv'!$C:$C,'det_prop vgv'!$A:$A,VGV!$B9,'det_prop vgv'!$D:$D,V$13) -> 0 | W9: =SUMIFS(orçvgv!$C:$C,orçvgv!$B:$B,VGV!$B9,orçvgv!$D:$D,W$13) -> 9293500.6 | X9: =SUMIFS('det_prop vgv'!$C:$C,'det_prop vgv'!$A:$A,VGV!$B9,'det_prop vgv'!$D:$D,X$13) -> 0 | Y9: =SUMIFS(orçvgv!$C:$C,orçvgv!$B:$B,VGV!$B9,orçvgv!$D:$D,Y$13) -> 9353908.4 | Z9: =SUMIFS('det_prop vgv'!$C:$C,'det_prop vgv'!$A:$A,VGV!$B9,'det_prop vgv'!$D:$D,Z$13) -> 0 | AA9: 67306889 | AB9: 98161799 | AC9: 9114608 | AD9: 10295489
B10: SENSIA RP | C10: =SUMIFS(orçvgv!$C:$C,orçvgv!$B:$B,VGV!$B10,orçvgv!$D:$D,C$13) -> 2507732.5 | D10: =SUMIFS('det_prop vgv'!$C:$C,'det_prop vgv'!$A:$A,VGV!$B10,'det_prop vgv'!$D:$D,D$13) -> 911800 | E10: =SUMIFS(orçvgv!$C:$C,orçvgv!$B:$B,VGV!$B10,orçvgv!$D:$D,E$13) -> 1970457.8 | F10: =SUMIFS('det_prop vgv'!$C:$C,'det_prop vgv'!$A:$A,VGV!$B10,'det_prop vgv'!$D:$D,F$13) -> 646180.5 | G10: =SUMIFS(orçvgv!$C:$C,orçvgv!$B:$B,VGV!$B10,orçvgv!$D:$D,G$13) -> 2540439 | H10: =SUMIFS('det_prop vgv'!$C:$C,'det_prop vgv'!$A:$A,VGV!$B10,'det_prop vgv'!$D:$D,H$13) -> 2571871.3 | I10: =SUMIFS(orçvgv!$C:$C,orçvgv!$B:$B,VGV!$B10,orçvgv!$D:$D,I$13) -> 2556951.9 | J10: =SUMIFS('det_prop vgv'!$C:$C,'det_prop vgv'!$A:$A,VGV!$B10,'det_prop vgv'!$D:$D,J$13) -> 2014801.1 | K10: =SUMIFS(orçvgv!$C:$C,orçvgv!$B:$B,VGV!$B10,orçvgv!$D:$D,K$13) -> 2573572.1 | L10: =SUMIFS('det_prop vgv'!$C:$C,'det_prop vgv'!$A:$A,VGV!$B10,'det_prop vgv'!$D:$D,L$13) -> 0 | M10: =SUMIFS(orçvgv!$C:$C,orçvgv!$B:$B,VGV!$B10,orçvgv!$D:$D,M$13) -> 2590300.3 | N10: =SUMIFS('det_prop vgv'!$C:$C,'det_prop vgv'!$A:$A,VGV!$B10,'det_prop vgv'!$D:$D,N$13) -> 1543629.3 | O10: =SUMIFS(orçvgv!$C:$C,orçvgv!$B:$B,VGV!$B10,orçvgv!$D:$D,O$13) -> 3178938.8 | P10: =SUMIFS('det_prop vgv'!$C:$C,'det_prop vgv'!$A:$A,VGV!$B10,'det_prop vgv'!$D:$D,P$13) -> 1071580.3 | Q10: =SUMIFS(orçvgv!$C:$C,orçvgv!$B:$B,VGV!$B10,orçvgv!$D:$D,Q$13) -> 3199601.9 | R10: =SUMIFS('det_prop vgv'!$C:$C,'det_prop vgv'!$A:$A,VGV!$B10,'det_prop vgv'!$D:$D,R$13) -> 1655241.9 | S10: =SUMIFS(orçvgv!$C:$C,orçvgv!$B:$B,VGV!$B10,orçvgv!$D:$D,S$13) -> 3220399.3 | T10: =SUMIFS('det_prop vgv'!$C:$C,'det_prop vgv'!$A:$A,VGV!$B10,'det_prop vgv'!$D:$D,T$13) -> 1142340.5 | U10: =SUMIFS(orçvgv!$C:$C,orçvgv!$B:$B,VGV!$B10,orçvgv!$D:$D,U$13) -> 3241331.9 | V10: =SUMIFS('det_prop vgv'!$C:$C,'det_prop vgv'!$A:$A,VGV!$B10,'det_prop vgv'!$D:$D,V$13) -> 0 | W10: =SUMIFS(orçvgv!$C:$C,orçvgv!$B:$B,VGV!$B10,orçvgv!$D:$D,W$13) -> 3262400.6 | X10: =SUMIFS('det_prop vgv'!$C:$C,'det_prop vgv'!$A:$A,VGV!$B10,'det_prop vgv'!$D:$D,X$13) -> 0 | Y10: =SUMIFS(orçvgv!$C:$C,orçvgv!$B:$B,VGV!$B10,orçvgv!$D:$D,Y$13) -> 3283606.2 | Z10: =SUMIFS('det_prop vgv'!$C:$C,'det_prop vgv'!$A:$A,VGV!$B10,'det_prop vgv'!$D:$D,Z$13) -> 0 | AA10: 21117994 | AB10: 10415104 | AC10: 3199601.9 | AD10: 1655241.9
B11: SENSIA | C11: =SUM(C9:C10) -> 10943783 | D11: =SUM(D10,D9) -> 7584594.8 | E11: =SUM(E9:E10) -> 9004883 | F11: =SUM(F10,F9) -> 12238209 | G11: =SUM(G9:G10) -> 10531819 | H11: =SUM(H10,H9) -> 16667621 | I11: =SUM(I9:I10) -> 10600276 | J11: =SUM(J10,J9) -> 9023414.7 | K11: =SUM(K9:K10) -> 11411700 | L11: =SUM(L10,L9) -> 18788579 | M11: =SUM(M9:M10) -> 11485876 | N11: =SUM(N10,N9) -> 15978986 | O11: =SUM(O9:O10) -> 12132336 | P11: =SUM(P10,P9) -> 16344768 | Q11: =SUM(Q9:Q10) -> 12314210 | R11: =SUM(R10,R9) -> 11950731 | S11: =SUM(S9:S10) -> 13021014 | T11: =SUM(T10,T9) -> 13937142 | U11: =SUM(U9:U10) -> 12474815 | V11: =SUM(V10,V9) -> 0 | W11: =SUM(W9:W10) -> 12555901 | X11: =SUM(X10,X9) -> 0 | Y11: =SUM(Y9:Y10) -> 12637515 | Z11: =SUM(Z10,Z9) -> 0 | AA11: =SUM(AA10,AA9) -> 88424883 | AB11: =SUM(AB10,AB9) -> 1.085769e+08 | AC11: 12314210 | AD11: 11950731
B12: (Tudo) | C12: =SUM(C3:C10) -> 1.531532e+08 | D12: =SUM(D3:D10) -> 1.1459661e+08 | E12: =SUM(E3:E10) -> 1.3001754e+08 | F12: =SUM(F3:F10) -> 1.1086357e+08 | G12: =SUM(G3:G10) -> 1.7154679e+08 | H12: =SUM(H3:H10) -> 2.017141e+08 | I12: =SUM(I3:I10) -> 1.7188652e+08 | J12: =SUM(J3:J10) -> 1.6570804e+08 | ... Z12: =SUM(Z3:Z10) -> 0 | AA12: =SUM(_xlfn.ANCHORARRAY(AA3)) -> 1.3359981e+09 | AB12: =SUM(_xlfn.ANCHORARRAY(AB3)) -> 1.1787745e+09 | AC12: =SUM(AC3:AC10) -> 1.7364695e+08 | AD12: =SUM(AD3:AD10) -> 1.2059383e+08
A13: =DATE($A$15,[3]GERAL!$E$3,1) -> 46235 | C13: 1 | D13: 1 | E13: 2 | F13: 2 | G13: 3 | H13: 3 | I13: 4 | J13: 4 | K13: 5 | L13: 5 | M13: 6 | N13: 6 | O13: 7 | P13: 7 | Q13: 8 | R13: 8 | S13: 9 | T13: 9 | U13: 10 | V13: 10 | W13: 11 | X13: 11 | Y13: 12 | Z13: 12
A14: ANO | C14: =_xlfn.CONCAT(C2,C13) -> VGV META1 | D14: =_xlfn.CONCAT(D2,D13) -> VGV REAL1 | E14: =_xlfn.CONCAT(E2,E13) -> VGV META2 | F14: =_xlfn.CONCAT(F2,F13) -> VGV REAL2 | G14: =_xlfn.CONCAT(G2,G13) -> VGV META3 | H14: =_xlfn.CONCAT(H2,H13) -> VGV REAL3 | I14: =_xlfn.CONCAT(I2,I13) -> VGV META4 | J14: =_xlfn.CONCAT(J2,J13) -> VGV REAL4 | ... Z14: =_xlfn.CONCAT(Z2,Z13) -> VGV REAL12
A15: 2026 | C15: JANEIRO | E15: FEVEREIRO | G15: MARÇO | I15: ABRIL | K15: MAIO | M15: JUNHO | O15: JULHO | Q15: AGOSTO | S15: SETEMBRO | U15: OUTUBRO | W15: NOVEMBRO | Y15: DEZEMBRO | AA15: YTD | AC15: MÊS ATUAL
A16: NÃO PRECISA ATUALIZAR | B16: Regional | C16: % VGV META | D16: % VGV REAL | E16: % VGV META | F16: % VGV REAL | G16: % VGV META | H16: % VGV REAL | I16: % VGV META | J16: % VGV REAL | K16: % VGV META | L16: % VGV REAL | M16: % VGV META | N16: % VGV REAL | O16: % VGV META | P16: % VGV REAL | Q16: % VGV META | R16: % VGV REAL | S16: % VGV META | T16: % VGV REAL | U16: % VGV META | V16: % VGV REAL | W16: % VGV META | X16: % VGV REAL | Y16: % VGV META | Z16: % VGV REAL | AA16: VGV META | AB16: VGV REAL | AC16: VGV META | AD16: VGV REAL
B17: SP INT 1 | C17: =IFERROR(SUMIFS([3]BASE_METAXREAL!$P$4:$P$22549,[3]BASE_METAXREAL!$W$4:$W$22549,$B17,[3]BASE_METAXREAL!$B$4:$B$22549,C$13)/C3,0) -> 0 | D17: =IFERROR(SUMIFS([3]BASE_METAXREAL!$O$4:$O$22549,[3]BASE_METAXREAL!$W$4:$W$22549,$B17,[3]BASE_METAXREAL!$B$4:$B$22549,D$13)/D3,0) -> 0 | E17: =IFERROR(SUMIFS([3]BASE_METAXREAL!$P$4:$P$22549,[3]BASE_METAXREAL!$W$4:$W$22549,$B17,[3]BASE_METAXREAL!$B$4:$B$22549,E$13)/E3,0) -> 0 | F17: =IFERROR(SUMIFS([3]BASE_METAXREAL!$O$4:$O$22549,[3]BASE_METAXREAL!$W$4:$W$22549,$B17,[3]BASE_METAXREAL!$B$4:$B$22549,F$13)/F3,0) -> 0 | G17: =IFERROR(SUMIFS([3]BASE_METAXREAL!$P$4:$P$22549,[3]BASE_METAXREAL!$W$4:$W$22549,$B17,[3]BASE_METAXREAL!$B$4:$B$22549,G$13)/G3,0) -> 0 | H17: =IFERROR(SUMIFS([3]BASE_METAXREAL!$O$4:$O$22549,[3]BASE_METAXREAL!$W$4:$W$22549,$B17,[3]BASE_METAXREAL!$B$4:$B$22549,H$13)/H3,0) -> 0 | I17: =IFERROR(SUMIFS([3]BASE_METAXREAL!$P$4:$P$22549,[3]BASE_METAXREAL!$W$4:$W$22549,$B17,[3]BASE_METAXREAL!$B$4:$B$22549,I$13)/I3,0) -> 0 | J17: =IFERROR(SUMIFS([3]BASE_METAXREAL!$O$4:$O$22549,[3]BASE_METAXREAL!$W$4:$W$22549,$B17,[3]BASE_METAXREAL!$B$4:$B$22549,J$13)/J3,0) -> 0 | K17: =IFERROR(SUMIFS([3]BASE_METAXREAL!$P$4:$P$22549,[3]BASE_METAXREAL!$W$4:$W$22549,$B17,[3]BASE_METAXREAL!$B$4:$B$22549,K$13)/K3,0) -> 0 | L17: =IFERROR(SUMIFS([3]BASE_METAXREAL!$O$4:$O$22549,[3]BASE_METAXREAL!$W$4:$W$22549,$B17,[3]BASE_METAXREAL!$B$4:$B$22549,L$13)/L3,0) -> 0 | M17: =IFERROR(SUMIFS([3]BASE_METAXREAL!$P$4:$P$22549,[3]BASE_METAXREAL!$W$4:$W$22549,$B17,[3]BASE_METAXREAL!$B$4:$B$22549,M$13)/M3,0) -> 0 | N17: =IFERROR(SUMIFS([3]BASE_METAXREAL!$O$4:$O$22549,[3]BASE_METAXREAL!$W$4:$W$22549,$B17,[3]BASE_METAXREAL!$B$4:$B$22549,N$13)/N3,0) -> 0 | O17: =IFERROR(SUMIFS([3]BASE_METAXREAL!$P$4:$P$22549,[3]BASE_METAXREAL!$W$4:$W$22549,$B17,[3]BASE_METAXREAL!$B$4:$B$22549,O$13)/O3,0) -> 0 | P17: =IFERROR(SUMIFS([3]BASE_METAXREAL!$O$4:$O$22549,[3]BASE_METAXREAL!$W$4:$W$22549,$B17,[3]BASE_METAXREAL!$B$4:$B$22549,P$13)/P3,0) -> 0 | Q17: =IFERROR(SUMIFS([3]BASE_METAXREAL!$P$4:$P$22549,[3]BASE_METAXREAL!$W$4:$W$22549,$B17,[3]BASE_METAXREAL!$B$4:$B$22549,Q$13)/Q3,0) -> 0 | R17: =IFERROR(SUMIFS([3]BASE_METAXREAL!$O$4:$O$22549,[3]BASE_METAXREAL!$W$4:$W$22549,$B17,[3]BASE_METAXREAL!$B$4:$B$22549,R$13)/R3,0) -> 0 | S17: =IFERROR(SUMIFS([3]BASE_METAXREAL!$P$4:$P$22549,[3]BASE_METAXREAL!$W$4:$W$22549,$B17,[3]BASE_METAXREAL!$B$4:$B$22549,S$13)/S3,0) -> 0 | T17: =IFERROR(SUMIFS([3]BASE_METAXREAL!$O$4:$O$22549,[3]BASE_METAXREAL!$W$4:$W$22549,$B17,[3]BASE_METAXREAL!$B$4:$B$22549,T$13)/T3,0) -> 0 | U17: =IFERROR(SUMIFS([3]BASE_METAXREAL!$P$4:$P$22549,[3]BASE_METAXREAL!$W$4:$W$22549,$B17,[3]BASE_METAXREAL!$B$4:$B$22549,U$13)/U3,0) -> 0 | V17: =IFERROR(SUMIFS([3]BASE_METAXREAL!$O$4:$O$22549,[3]BASE_METAXREAL!$W$4:$W$22549,$B17,[3]BASE_METAXREAL!$B$4:$B$22549,V$13)/V3,0) -> 0 | W17: =IFERROR(SUMIFS([3]BASE_METAXREAL!$P$4:$P$22549,[3]BASE_METAXREAL!$W$4:$W$22549,$B17,[3]BASE_METAXREAL!$B$4:$B$22549,W$13)/W3,0) -> 0 | X17: =IFERROR(SUMIFS([3]BASE_METAXREAL!$O$4:$O$22549,[3]BASE_METAXREAL!$W$4:$W$22549,$B17,[3]BASE_METAXREAL!$B$4:$B$22549,X$13)/X3,0) -> 0 | Y17: =IFERROR(SUMIFS([3]BASE_METAXREAL!$P$4:$P$22549,[3]BASE_METAXREAL!$W$4:$W$22549,$B17,[3]BASE_METAXREAL!$B$4:$B$22549,Y$13)/Y3,0) -> 0 | Z17: =IFERROR(SUMIFS([3]BASE_METAXREAL!$O$4:$O$22549,[3]BASE_METAXREAL!$W$4:$W$22549,$B17,[3]BASE_METAXREAL!$B$4:$B$22549,Z$13)/Z3,0) -> 0 | AA17: =(SUMIFS([3]BASE_METAXREAL!$P$4:$P$22549,[3]BASE_METAXREAL!$W$4:$W$22549,B17,[3]BASE_METAXREAL!$K$4:$K$22549,"<>COMISSÕES E PREMIAÇÕES (Contratada)",[3]BASE_METAXREAL!$B$4:$B$22549,"<="&MONTH($A$13))/AA3)+ (SUMIFS([3]BASE_METAXREAL!$P$4:$P$22549,[3]BASE_METAXREAL!$W$4:$W$22549,B17,[3]BASE_METAXREAL!$K$4:$K$22549,"=COMISSÕES E PREMIAÇÕES (Contratada)",[3]BASE_METAXREAL!$B$4:$B$22549,"<="&MONTH($A$13))/AB3) -> #VALUE! | AB17: =(SUMIFS([3]BASE_METAXREAL!$O$4:$O$22549,[3]BASE_METAXREAL!$W$4:$W$22549,B17,[3]BASE_METAXREAL!$B$4:$B$22549,"<="&MONTH($A$13))/AB3) -> #VALUE! | AC17: =IFERROR((SUMIFS([3]BASE_METAXREAL!$P$4:$P$22549,[3]BASE_METAXREAL!$W$4:$W$22549,B17,[3]BASE_METAXREAL!$K$4:$K$22549,"<>COMISSÕES E PREMIAÇÕES (Contratada)",[3]BASE_METAXREAL!$B$4:$B$22549,MONTH($A$13))/AC3),0)+ IFERROR((SUMIFS([3]BASE_METAXREAL!$P$4:$P$22549,[3]BASE_METAXREAL!$W$4:$W$22549,B17,[3]BASE_METAXREAL!$K$4:$K$22549,"=COMISSÕES E PREMIAÇÕES (Contratada)",[3]BASE_METAXREAL!$B$4:$B$22549,MONTH($A$13))/AD3),0) -> 0 | AD17: =SUMIFS([3]BASE_METAXREAL!$O$4:$O$22549,[3]BASE_METAXREAL!$W$4:$W$22549,B17,[3]BASE_METAXREAL!$B$4:$B$22549,MONTH($A$13))/AD3 -> #VALUE!
B18: SP INT 2 | C18: =IFERROR(SUMIFS([3]BASE_METAXREAL!$P$4:$P$22549,[3]BASE_METAXREAL!$W$4:$W$22549,$B18,[3]BASE_METAXREAL!$B$4:$B$22549,C$13)/C4,0) -> 0 | D18: =IFERROR(SUMIFS([3]BASE_METAXREAL!$O$4:$O$22549,[3]BASE_METAXREAL!$W$4:$W$22549,$B18,[3]BASE_METAXREAL!$B$4:$B$22549,D$13)/D4,0) -> 0 | E18: =IFERROR(SUMIFS([3]BASE_METAXREAL!$P$4:$P$22549,[3]BASE_METAXREAL!$W$4:$W$22549,$B18,[3]BASE_METAXREAL!$B$4:$B$22549,E$13)/E4,0) -> 0 | F18: =IFERROR(SUMIFS([3]BASE_METAXREAL!$O$4:$O$22549,[3]BASE_METAXREAL!$W$4:$W$22549,$B18,[3]BASE_METAXREAL!$B$4:$B$22549,F$13)/F4,0) -> 0 | G18: =IFERROR(SUMIFS([3]BASE_METAXREAL!$P$4:$P$22549,[3]BASE_METAXREAL!$W$4:$W$22549,$B18,[3]BASE_METAXREAL!$B$4:$B$22549,G$13)/G4,0) -> 0 | H18: =IFERROR(SUMIFS([3]BASE_METAXREAL!$O$4:$O$22549,[3]BASE_METAXREAL!$W$4:$W$22549,$B18,[3]BASE_METAXREAL!$B$4:$B$22549,H$13)/H4,0) -> 0 | I18: =IFERROR(SUMIFS([3]BASE_METAXREAL!$P$4:$P$22549,[3]BASE_METAXREAL!$W$4:$W$22549,$B18,[3]BASE_METAXREAL!$B$4:$B$22549,I$13)/I4,0) -> 0 | J18: =IFERROR(SUMIFS([3]BASE_METAXREAL!$O$4:$O$22549,[3]BASE_METAXREAL!$W$4:$W$22549,$B18,[3]BASE_METAXREAL!$B$4:$B$22549,J$13)/J4,0) -> 0 | K18: =IFERROR(SUMIFS([3]BASE_METAXREAL!$P$4:$P$22549,[3]BASE_METAXREAL!$W$4:$W$22549,$B18,[3]BASE_METAXREAL!$B$4:$B$22549,K$13)/K4,0) -> 0 | L18: =IFERROR(SUMIFS([3]BASE_METAXREAL!$O$4:$O$22549,[3]BASE_METAXREAL!$W$4:$W$22549,$B18,[3]BASE_METAXREAL!$B$4:$B$22549,L$13)/L4,0) -> 0 | M18: =IFERROR(SUMIFS([3]BASE_METAXREAL!$P$4:$P$22549,[3]BASE_METAXREAL!$W$4:$W$22549,$B18,[3]BASE_METAXREAL!$B$4:$B$22549,M$13)/M4,0) -> 0 | N18: =IFERROR(SUMIFS([3]BASE_METAXREAL!$O$4:$O$22549,[3]BASE_METAXREAL!$W$4:$W$22549,$B18,[3]BASE_METAXREAL!$B$4:$B$22549,N$13)/N4,0) -> 0 | O18: =IFERROR(SUMIFS([3]BASE_METAXREAL!$P$4:$P$22549,[3]BASE_METAXREAL!$W$4:$W$22549,$B18,[3]BASE_METAXREAL!$B$4:$B$22549,O$13)/O4,0) -> 0 | P18: =IFERROR(SUMIFS([3]BASE_METAXREAL!$O$4:$O$22549,[3]BASE_METAXREAL!$W$4:$W$22549,$B18,[3]BASE_METAXREAL!$B$4:$B$22549,P$13)/P4,0) -> 0 | Q18: =IFERROR(SUMIFS([3]BASE_METAXREAL!$P$4:$P$22549,[3]BASE_METAXREAL!$W$4:$W$22549,$B18,[3]BASE_METAXREAL!$B$4:$B$22549,Q$13)/Q4,0) -> 0 | R18: =IFERROR(SUMIFS([3]BASE_METAXREAL!$O$4:$O$22549,[3]BASE_METAXREAL!$W$4:$W$22549,$B18,[3]BASE_METAXREAL!$B$4:$B$22549,R$13)/R4,0) -> 0 | S18: =IFERROR(SUMIFS([3]BASE_METAXREAL!$P$4:$P$22549,[3]BASE_METAXREAL!$W$4:$W$22549,$B18,[3]BASE_METAXREAL!$B$4:$B$22549,S$13)/S4,0) -> 0 | T18: =IFERROR(SUMIFS([3]BASE_METAXREAL!$O$4:$O$22549,[3]BASE_METAXREAL!$W$4:$W$22549,$B18,[3]BASE_METAXREAL!$B$4:$B$22549,T$13)/T4,0) -> 0 | U18: =IFERROR(SUMIFS([3]BASE_METAXREAL!$P$4:$P$22549,[3]BASE_METAXREAL!$W$4:$W$22549,$B18,[3]BASE_METAXREAL!$B$4:$B$22549,U$13)/U4,0) -> 0 | V18: =IFERROR(SUMIFS([3]BASE_METAXREAL!$O$4:$O$22549,[3]BASE_METAXREAL!$W$4:$W$22549,$B18,[3]BASE_METAXREAL!$B$4:$B$22549,V$13)/V4,0) -> 0 | W18: =IFERROR(SUMIFS([3]BASE_METAXREAL!$P$4:$P$22549,[3]BASE_METAXREAL!$W$4:$W$22549,$B18,[3]BASE_METAXREAL!$B$4:$B$22549,W$13)/W4,0) -> 0 | X18: =IFERROR(SUMIFS([3]BASE_METAXREAL!$O$4:$O$22549,[3]BASE_METAXREAL!$W$4:$W$22549,$B18,[3]BASE_METAXREAL!$B$4:$B$22549,X$13)/X4,0) -> 0 | Y18: =IFERROR(SUMIFS([3]BASE_METAXREAL!$P$4:$P$22549,[3]BASE_METAXREAL!$W$4:$W$22549,$B18,[3]BASE_METAXREAL!$B$4:$B$22549,Y$13)/Y4,0) -> 0 | Z18: =IFERROR(SUMIFS([3]BASE_METAXREAL!$O$4:$O$22549,[3]BASE_METAXREAL!$W$4:$W$22549,$B18,[3]BASE_METAXREAL!$B$4:$B$22549,Z$13)/Z4,0) -> 0 | AA18: =(SUMIFS([3]BASE_METAXREAL!$P$4:$P$22549,[3]BASE_METAXREAL!$W$4:$W$22549,B18,[3]BASE_METAXREAL!$K$4:$K$22549,"<>COMISSÕES E PREMIAÇÕES (Contratada)",[3]BASE_METAXREAL!$B$4:$B$22549,"<="&MONTH($A$13))/AA4)+ (SUMIFS([3]BASE_METAXREAL!$P$4:$P$22549,[3]BASE_METAXREAL!$W$4:$W$22549,B18,[3]BASE_METAXREAL!$K$4:$K$22549,"=COMISSÕES E PREMIAÇÕES (Contratada)",[3]BASE_METAXREAL!$B$4:$B$22549,"<="&MONTH($A$13))/AB4) -> #VALUE! | AB18: =(SUMIFS([3]BASE_METAXREAL!$O$4:$O$22549,[3]BASE_METAXREAL!$W$4:$W$22549,B18,[3]BASE_METAXREAL!$B$4:$B$22549,"<="&MONTH($A$13))/AB4) -> #VALUE! | AC18: =IFERROR((SUMIFS([3]BASE_METAXREAL!$P$4:$P$22549,[3]BASE_METAXREAL!$W$4:$W$22549,B18,[3]BASE_METAXREAL!$K$4:$K$22549,"<>COMISSÕES E PREMIAÇÕES (Contratada)",[3]BASE_METAXREAL!$B$4:$B$22549,MONTH($A$13))/AC4),0)+ IFERROR((SUMIFS([3]BASE_METAXREAL!$P$4:$P$22549,[3]BASE_METAXREAL!$W$4:$W$22549,B18,[3]BASE_METAXREAL!$K$4:$K$22549,"=COMISSÕES E PREMIAÇÕES (Contratada)",[3]BASE_METAXREAL!$B$4:$B$22549,MONTH($A$13))/AD4),0) -> 0 | AD18: =SUMIFS([3]BASE_METAXREAL!$O$4:$O$22549,[3]BASE_METAXREAL!$W$4:$W$22549,B18,[3]BASE_METAXREAL!$B$4:$B$22549,MONTH($A$13))/AD4 -> #VALUE!
B19: SP INT 3 | C19: =IFERROR(SUMIFS([3]BASE_METAXREAL!$P$4:$P$22549,[3]BASE_METAXREAL!$W$4:$W$22549,$B19,[3]BASE_METAXREAL!$B$4:$B$22549,C$13)/C5,0) -> 0 | D19: =IFERROR(SUMIFS([3]BASE_METAXREAL!$O$4:$O$22549,[3]BASE_METAXREAL!$W$4:$W$22549,$B19,[3]BASE_METAXREAL!$B$4:$B$22549,D$13)/D5,0) -> 0 | E19: =IFERROR(SUMIFS([3]BASE_METAXREAL!$P$4:$P$22549,[3]BASE_METAXREAL!$W$4:$W$22549,$B19,[3]BASE_METAXREAL!$B$4:$B$22549,E$13)/E5,0) -> 0 | F19: =IFERROR(SUMIFS([3]BASE_METAXREAL!$O$4:$O$22549,[3]BASE_METAXREAL!$W$4:$W$22549,$B19,[3]BASE_METAXREAL!$B$4:$B$22549,F$13)/F5,0) -> 0 | G19: =IFERROR(SUMIFS([3]BASE_METAXREAL!$P$4:$P$22549,[3]BASE_METAXREAL!$W$4:$W$22549,$B19,[3]BASE_METAXREAL!$B$4:$B$22549,G$13)/G5,0) -> 0 | H19: =IFERROR(SUMIFS([3]BASE_METAXREAL!$O$4:$O$22549,[3]BASE_METAXREAL!$W$4:$W$22549,$B19,[3]BASE_METAXREAL!$B$4:$B$22549,H$13)/H5,0) -> 0 | I19: =IFERROR(SUMIFS([3]BASE_METAXREAL!$P$4:$P$22549,[3]BASE_METAXREAL!$W$4:$W$22549,$B19,[3]BASE_METAXREAL!$B$4:$B$22549,I$13)/I5,0) -> 0 | J19: =IFERROR(SUMIFS([3]BASE_METAXREAL!$O$4:$O$22549,[3]BASE_METAXREAL!$W$4:$W$22549,$B19,[3]BASE_METAXREAL!$B$4:$B$22549,J$13)/J5,0) -> 0 | K19: =IFERROR(SUMIFS([3]BASE_METAXREAL!$P$4:$P$22549,[3]BASE_METAXREAL!$W$4:$W$22549,$B19,[3]BASE_METAXREAL!$B$4:$B$22549,K$13)/K5,0) -> 0 | L19: =IFERROR(SUMIFS([3]BASE_METAXREAL!$O$4:$O$22549,[3]BASE_METAXREAL!$W$4:$W$22549,$B19,[3]BASE_METAXREAL!$B$4:$B$22549,L$13)/L5,0) -> 0 | M19: =IFERROR(SUMIFS([3]BASE_METAXREAL!$P$4:$P$22549,[3]BASE_METAXREAL!$W$4:$W$22549,$B19,[3]BASE_METAXREAL!$B$4:$B$22549,M$13)/M5,0) -> 0 | N19: =IFERROR(SUMIFS([3]BASE_METAXREAL!$O$4:$O$22549,[3]BASE_METAXREAL!$W$4:$W$22549,$B19,[3]BASE_METAXREAL!$B$4:$B$22549,N$13)/N5,0) -> 0 | O19: =IFERROR(SUMIFS([3]BASE_METAXREAL!$P$4:$P$22549,[3]BASE_METAXREAL!$W$4:$W$22549,$B19,[3]BASE_METAXREAL!$B$4:$B$22549,O$13)/O5,0) -> 0 | P19: =IFERROR(SUMIFS([3]BASE_METAXREAL!$O$4:$O$22549,[3]BASE_METAXREAL!$W$4:$W$22549,$B19,[3]BASE_METAXREAL!$B$4:$B$22549,P$13)/P5,0) -> 0 | Q19: =IFERROR(SUMIFS([3]BASE_METAXREAL!$P$4:$P$22549,[3]BASE_METAXREAL!$W$4:$W$22549,$B19,[3]BASE_METAXREAL!$B$4:$B$22549,Q$13)/Q5,0) -> 0 | R19: =IFERROR(SUMIFS([3]BASE_METAXREAL!$O$4:$O$22549,[3]BASE_METAXREAL!$W$4:$W$22549,$B19,[3]BASE_METAXREAL!$B$4:$B$22549,R$13)/R5,0) -> 0 | S19: =IFERROR(SUMIFS([3]BASE_METAXREAL!$P$4:$P$22549,[3]BASE_METAXREAL!$W$4:$W$22549,$B19,[3]BASE_METAXREAL!$B$4:$B$22549,S$13)/S5,0) -> 0 | T19: =IFERROR(SUMIFS([3]BASE_METAXREAL!$O$4:$O$22549,[3]BASE_METAXREAL!$W$4:$W$22549,$B19,[3]BASE_METAXREAL!$B$4:$B$22549,T$13)/T5,0) -> 0 | U19: =IFERROR(SUMIFS([3]BASE_METAXREAL!$P$4:$P$22549,[3]BASE_METAXREAL!$W$4:$W$22549,$B19,[3]BASE_METAXREAL!$B$4:$B$22549,U$13)/U5,0) -> 0 | V19: =IFERROR(SUMIFS([3]BASE_METAXREAL!$O$4:$O$22549,[3]BASE_METAXREAL!$W$4:$W$22549,$B19,[3]BASE_METAXREAL!$B$4:$B$22549,V$13)/V5,0) -> 0 | W19: =IFERROR(SUMIFS([3]BASE_METAXREAL!$P$4:$P$22549,[3]BASE_METAXREAL!$W$4:$W$22549,$B19,[3]BASE_METAXREAL!$B$4:$B$22549,W$13)/W5,0) -> 0 | X19: =IFERROR(SUMIFS([3]BASE_METAXREAL!$O$4:$O$22549,[3]BASE_METAXREAL!$W$4:$W$22549,$B19,[3]BASE_METAXREAL!$B$4:$B$22549,X$13)/X5,0) -> 0 | Y19: =IFERROR(SUMIFS([3]BASE_METAXREAL!$P$4:$P$22549,[3]BASE_METAXREAL!$W$4:$W$22549,$B19,[3]BASE_METAXREAL!$B$4:$B$22549,Y$13)/Y5,0) -> 0 | Z19: =IFERROR(SUMIFS([3]BASE_METAXREAL!$O$4:$O$22549,[3]BASE_METAXREAL!$W$4:$W$22549,$B19,[3]BASE_METAXREAL!$B$4:$B$22549,Z$13)/Z5,0) -> 0 | AA19: =(SUMIFS([3]BASE_METAXREAL!$P$4:$P$22549,[3]BASE_METAXREAL!$W$4:$W$22549,B19,[3]BASE_METAXREAL!$K$4:$K$22549,"<>COMISSÕES E PREMIAÇÕES (Contratada)",[3]BASE_METAXREAL!$B$4:$B$22549,"<="&MONTH($A$13))/AA5)+ (SUMIFS([3]BASE_METAXREAL!$P$4:$P$22549,[3]BASE_METAXREAL!$W$4:$W$22549,B19,[3]BASE_METAXREAL!$K$4:$K$22549,"=COMISSÕES E PREMIAÇÕES (Contratada)",[3]BASE_METAXREAL!$B$4:$B$22549,"<="&MONTH($A$13))/AB5) -> #VALUE! | AB19: =(SUMIFS([3]BASE_METAXREAL!$O$4:$O$22549,[3]BASE_METAXREAL!$W$4:$W$22549,B19,[3]BASE_METAXREAL!$B$4:$B$22549,"<="&MONTH($A$13))/AB5) -> #VALUE! | AC19: =IFERROR((SUMIFS([3]BASE_METAXREAL!$P$4:$P$22549,[3]BASE_METAXREAL!$W$4:$W$22549,B19,[3]BASE_METAXREAL!$K$4:$K$22549,"<>COMISSÕES E PREMIAÇÕES (Contratada)",[3]BASE_METAXREAL!$B$4:$B$22549,MONTH($A$13))/AC5),0)+ IFERROR((SUMIFS([3]BASE_METAXREAL!$P$4:$P$22549,[3]BASE_METAXREAL!$W$4:$W$22549,B19,[3]BASE_METAXREAL!$K$4:$K$22549,"=COMISSÕES E PREMIAÇÕES (Contratada)",[3]BASE_METAXREAL!$B$4:$B$22549,MONTH($A$13))/AD5),0) -> 0 | AD19: =SUMIFS([3]BASE_METAXREAL!$O$4:$O$22549,[3]BASE_METAXREAL!$W$4:$W$22549,B19,[3]BASE_METAXREAL!$B$4:$B$22549,MONTH($A$13))/AD5 -> #VALUE!
B20: SP INT 4 | C20: =IFERROR(SUMIFS([3]BASE_METAXREAL!$P$4:$P$22549,[3]BASE_METAXREAL!$W$4:$W$22549,$B20,[3]BASE_METAXREAL!$B$4:$B$22549,C$13)/C6,0) -> 0 | D20: =IFERROR(SUMIFS([3]BASE_METAXREAL!$O$4:$O$22549,[3]BASE_METAXREAL!$W$4:$W$22549,$B20,[3]BASE_METAXREAL!$B$4:$B$22549,D$13)/D6,0) -> 0 | E20: =IFERROR(SUMIFS([3]BASE_METAXREAL!$P$4:$P$22549,[3]BASE_METAXREAL!$W$4:$W$22549,$B20,[3]BASE_METAXREAL!$B$4:$B$22549,E$13)/E6,0) -> 0 | F20: =IFERROR(SUMIFS([3]BASE_METAXREAL!$O$4:$O$22549,[3]BASE_METAXREAL!$W$4:$W$22549,$B20,[3]BASE_METAXREAL!$B$4:$B$22549,F$13)/F6,0) -> 0 | G20: =IFERROR(SUMIFS([3]BASE_METAXREAL!$P$4:$P$22549,[3]BASE_METAXREAL!$W$4:$W$22549,$B20,[3]BASE_METAXREAL!$B$4:$B$22549,G$13)/G6,0) -> 0 | H20: =IFERROR(SUMIFS([3]BASE_METAXREAL!$O$4:$O$22549,[3]BASE_METAXREAL!$W$4:$W$22549,$B20,[3]BASE_METAXREAL!$B$4:$B$22549,H$13)/H6,0) -> 0 | I20: =IFERROR(SUMIFS([3]BASE_METAXREAL!$P$4:$P$22549,[3]BASE_METAXREAL!$W$4:$W$22549,$B20,[3]BASE_METAXREAL!$B$4:$B$22549,I$13)/I6,0) -> 0 | J20: =IFERROR(SUMIFS([3]BASE_METAXREAL!$O$4:$O$22549,[3]BASE_METAXREAL!$W$4:$W$22549,$B20,[3]BASE_METAXREAL!$B$4:$B$22549,J$13)/J6,0) -> 0 | K20: =IFERROR(SUMIFS([3]BASE_METAXREAL!$P$4:$P$22549,[3]BASE_METAXREAL!$W$4:$W$22549,$B20,[3]BASE_METAXREAL!$B$4:$B$22549,K$13)/K6,0) -> 0 | L20: =IFERROR(SUMIFS([3]BASE_METAXREAL!$O$4:$O$22549,[3]BASE_METAXREAL!$W$4:$W$22549,$B20,[3]BASE_METAXREAL!$B$4:$B$22549,L$13)/L6,0) -> 0 | M20: =IFERROR(SUMIFS([3]BASE_METAXREAL!$P$4:$P$22549,[3]BASE_METAXREAL!$W$4:$W$22549,$B20,[3]BASE_METAXREAL!$B$4:$B$22549,M$13)/M6,0) -> 0 | N20: =IFERROR(SUMIFS([3]BASE_METAXREAL!$O$4:$O$22549,[3]BASE_METAXREAL!$W$4:$W$22549,$B20,[3]BASE_METAXREAL!$B$4:$B$22549,N$13)/N6,0) -> 0 | O20: =IFERROR(SUMIFS([3]BASE_METAXREAL!$P$4:$P$22549,[3]BASE_METAXREAL!$W$4:$W$22549,$B20,[3]BASE_METAXREAL!$B$4:$B$22549,O$13)/O6,0) -> 0 | P20: =IFERROR(SUMIFS([3]BASE_METAXREAL!$O$4:$O$22549,[3]BASE_METAXREAL!$W$4:$W$22549,$B20,[3]BASE_METAXREAL!$B$4:$B$22549,P$13)/P6,0) -> 0 | Q20: =IFERROR(SUMIFS([3]BASE_METAXREAL!$P$4:$P$22549,[3]BASE_METAXREAL!$W$4:$W$22549,$B20,[3]BASE_METAXREAL!$B$4:$B$22549,Q$13)/Q6,0) -> 0 | R20: =IFERROR(SUMIFS([3]BASE_METAXREAL!$O$4:$O$22549,[3]BASE_METAXREAL!$W$4:$W$22549,$B20,[3]BASE_METAXREAL!$B$4:$B$22549,R$13)/R6,0) -> 0 | S20: =IFERROR(SUMIFS([3]BASE_METAXREAL!$P$4:$P$22549,[3]BASE_METAXREAL!$W$4:$W$22549,$B20,[3]BASE_METAXREAL!$B$4:$B$22549,S$13)/S6,0) -> 0 | T20: =IFERROR(SUMIFS([3]BASE_METAXREAL!$O$4:$O$22549,[3]BASE_METAXREAL!$W$4:$W$22549,$B20,[3]BASE_METAXREAL!$B$4:$B$22549,T$13)/T6,0) -> 0 | U20: =IFERROR(SUMIFS([3]BASE_METAXREAL!$P$4:$P$22549,[3]BASE_METAXREAL!$W$4:$W$22549,$B20,[3]BASE_METAXREAL!$B$4:$B$22549,U$13)/U6,0) -> 0 | V20: =IFERROR(SUMIFS([3]BASE_METAXREAL!$O$4:$O$22549,[3]BASE_METAXREAL!$W$4:$W$22549,$B20,[3]BASE_METAXREAL!$B$4:$B$22549,V$13)/V6,0) -> 0 | W20: =IFERROR(SUMIFS([3]BASE_METAXREAL!$P$4:$P$22549,[3]BASE_METAXREAL!$W$4:$W$22549,$B20,[3]BASE_METAXREAL!$B$4:$B$22549,W$13)/W6,0) -> 0 | X20: =IFERROR(SUMIFS([3]BASE_METAXREAL!$O$4:$O$22549,[3]BASE_METAXREAL!$W$4:$W$22549,$B20,[3]BASE_METAXREAL!$B$4:$B$22549,X$13)/X6,0) -> 0 | Y20: =IFERROR(SUMIFS([3]BASE_METAXREAL!$P$4:$P$22549,[3]BASE_METAXREAL!$W$4:$W$22549,$B20,[3]BASE_METAXREAL!$B$4:$B$22549,Y$13)/Y6,0) -> 0 | Z20: =IFERROR(SUMIFS([3]BASE_METAXREAL!$O$4:$O$22549,[3]BASE_METAXREAL!$W$4:$W$22549,$B20,[3]BASE_METAXREAL!$B$4:$B$22549,Z$13)/Z6,0) -> 0 | AA20: =(SUMIFS([3]BASE_METAXREAL!$P$4:$P$22549,[3]BASE_METAXREAL!$W$4:$W$22549,B20,[3]BASE_METAXREAL!$K$4:$K$22549,"<>COMISSÕES E PREMIAÇÕES (Contratada)",[3]BASE_METAXREAL!$B$4:$B$22549,"<="&MONTH($A$13))/AA6)+ (SUMIFS([3]BASE_METAXREAL!$P$4:$P$22549,[3]BASE_METAXREAL!$W$4:$W$22549,B20,[3]BASE_METAXREAL!$K$4:$K$22549,"=COMISSÕES E PREMIAÇÕES (Contratada)",[3]BASE_METAXREAL!$B$4:$B$22549,"<="&MONTH($A$13))/AB6) -> #VALUE! | AB20: =(SUMIFS([3]BASE_METAXREAL!$O$4:$O$22549,[3]BASE_METAXREAL!$W$4:$W$22549,B20,[3]BASE_METAXREAL!$B$4:$B$22549,"<="&MONTH($A$13))/AB6) -> #VALUE! | AC20: =IFERROR((SUMIFS([3]BASE_METAXREAL!$P$4:$P$22549,[3]BASE_METAXREAL!$W$4:$W$22549,B20,[3]BASE_METAXREAL!$K$4:$K$22549,"<>COMISSÕES E PREMIAÇÕES (Contratada)",[3]BASE_METAXREAL!$B$4:$B$22549,MONTH($A$13))/AC6),0)+ IFERROR((SUMIFS([3]BASE_METAXREAL!$P$4:$P$22549,[3]BASE_METAXREAL!$W$4:$W$22549,B20,[3]BASE_METAXREAL!$K$4:$K$22549,"=COMISSÕES E PREMIAÇÕES (Contratada)",[3]BASE_METAXREAL!$B$4:$B$22549,MONTH($A$13))/AD6),0) -> 0 | AD20: =SUMIFS([3]BASE_METAXREAL!$O$4:$O$22549,[3]BASE_METAXREAL!$W$4:$W$22549,B20,[3]BASE_METAXREAL!$B$4:$B$22549,MONTH($A$13))/AD6 -> #VALUE!
B21: SP INT 5 | C21: =IFERROR(SUMIFS([3]BASE_METAXREAL!$P$4:$P$22549,[3]BASE_METAXREAL!$W$4:$W$22549,$B21,[3]BASE_METAXREAL!$B$4:$B$22549,C$13)/C7,0) -> 0 | D21: =IFERROR(SUMIFS([3]BASE_METAXREAL!$O$4:$O$22549,[3]BASE_METAXREAL!$W$4:$W$22549,$B21,[3]BASE_METAXREAL!$B$4:$B$22549,D$13)/D7,0) -> 0 | E21: =IFERROR(SUMIFS([3]BASE_METAXREAL!$P$4:$P$22549,[3]BASE_METAXREAL!$W$4:$W$22549,$B21,[3]BASE_METAXREAL!$B$4:$B$22549,E$13)/E7,0) -> 0 | F21: =IFERROR(SUMIFS([3]BASE_METAXREAL!$O$4:$O$22549,[3]BASE_METAXREAL!$W$4:$W$22549,$B21,[3]BASE_METAXREAL!$B$4:$B$22549,F$13)/F7,0) -> 0 | G21: =IFERROR(SUMIFS([3]BASE_METAXREAL!$P$4:$P$22549,[3]BASE_METAXREAL!$W$4:$W$22549,$B21,[3]BASE_METAXREAL!$B$4:$B$22549,G$13)/G7,0) -> 0 | H21: =IFERROR(SUMIFS([3]BASE_METAXREAL!$O$4:$O$22549,[3]BASE_METAXREAL!$W$4:$W$22549,$B21,[3]BASE_METAXREAL!$B$4:$B$22549,H$13)/H7,0) -> 0 | I21: =IFERROR(SUMIFS([3]BASE_METAXREAL!$P$4:$P$22549,[3]BASE_METAXREAL!$W$4:$W$22549,$B21,[3]BASE_METAXREAL!$B$4:$B$22549,I$13)/I7,0) -> 0 | J21: =IFERROR(SUMIFS([3]BASE_METAXREAL!$O$4:$O$22549,[3]BASE_METAXREAL!$W$4:$W$22549,$B21,[3]BASE_METAXREAL!$B$4:$B$22549,J$13)/J7,0) -> 0 | K21: =IFERROR(SUMIFS([3]BASE_METAXREAL!$P$4:$P$22549,[3]BASE_METAXREAL!$W$4:$W$22549,$B21,[3]BASE_METAXREAL!$B$4:$B$22549,K$13)/K7,0) -> 0 | L21: =IFERROR(SUMIFS([3]BASE_METAXREAL!$O$4:$O$22549,[3]BASE_METAXREAL!$W$4:$W$22549,$B21,[3]BASE_METAXREAL!$B$4:$B$22549,L$13)/L7,0) -> 0 | M21: =IFERROR(SUMIFS([3]BASE_METAXREAL!$P$4:$P$22549,[3]BASE_METAXREAL!$W$4:$W$22549,$B21,[3]BASE_METAXREAL!$B$4:$B$22549,M$13)/M7,0) -> 0 | N21: =IFERROR(SUMIFS([3]BASE_METAXREAL!$O$4:$O$22549,[3]BASE_METAXREAL!$W$4:$W$22549,$B21,[3]BASE_METAXREAL!$B$4:$B$22549,N$13)/N7,0) -> 0 | O21: =IFERROR(SUMIFS([3]BASE_METAXREAL!$P$4:$P$22549,[3]BASE_METAXREAL!$W$4:$W$22549,$B21,[3]BASE_METAXREAL!$B$4:$B$22549,O$13)/O7,0) -> 0 | P21: =IFERROR(SUMIFS([3]BASE_METAXREAL!$O$4:$O$22549,[3]BASE_METAXREAL!$W$4:$W$22549,$B21,[3]BASE_METAXREAL!$B$4:$B$22549,P$13)/P7,0) -> 0 | Q21: =IFERROR(SUMIFS([3]BASE_METAXREAL!$P$4:$P$22549,[3]BASE_METAXREAL!$W$4:$W$22549,$B21,[3]BASE_METAXREAL!$B$4:$B$22549,Q$13)/Q7,0) -> 0 | R21: =IFERROR(SUMIFS([3]BASE_METAXREAL!$O$4:$O$22549,[3]BASE_METAXREAL!$W$4:$W$22549,$B21,[3]BASE_METAXREAL!$B$4:$B$22549,R$13)/R7,0) -> 0 | S21: =IFERROR(SUMIFS([3]BASE_METAXREAL!$P$4:$P$22549,[3]BASE_METAXREAL!$W$4:$W$22549,$B21,[3]BASE_METAXREAL!$B$4:$B$22549,S$13)/S7,0) -> 0 | T21: =IFERROR(SUMIFS([3]BASE_METAXREAL!$O$4:$O$22549,[3]BASE_METAXREAL!$W$4:$W$22549,$B21,[3]BASE_METAXREAL!$B$4:$B$22549,T$13)/T7,0) -> 0 | U21: =IFERROR(SUMIFS([3]BASE_METAXREAL!$P$4:$P$22549,[3]BASE_METAXREAL!$W$4:$W$22549,$B21,[3]BASE_METAXREAL!$B$4:$B$22549,U$13)/U7,0) -> 0 | V21: =IFERROR(SUMIFS([3]BASE_METAXREAL!$O$4:$O$22549,[3]BASE_METAXREAL!$W$4:$W$22549,$B21,[3]BASE_METAXREAL!$B$4:$B$22549,V$13)/V7,0) -> 0 | W21: =IFERROR(SUMIFS([3]BASE_METAXREAL!$P$4:$P$22549,[3]BASE_METAXREAL!$W$4:$W$22549,$B21,[3]BASE_METAXREAL!$B$4:$B$22549,W$13)/W7,0) -> 0 | X21: =IFERROR(SUMIFS([3]BASE_METAXREAL!$O$4:$O$22549,[3]BASE_METAXREAL!$W$4:$W$22549,$B21,[3]BASE_METAXREAL!$B$4:$B$22549,X$13)/X7,0) -> 0 | Y21: =IFERROR(SUMIFS([3]BASE_METAXREAL!$P$4:$P$22549,[3]BASE_METAXREAL!$W$4:$W$22549,$B21,[3]BASE_METAXREAL!$B$4:$B$22549,Y$13)/Y7,0) -> 0 | Z21: =IFERROR(SUMIFS([3]BASE_METAXREAL!$O$4:$O$22549,[3]BASE_METAXREAL!$W$4:$W$22549,$B21,[3]BASE_METAXREAL!$B$4:$B$22549,Z$13)/Z7,0) -> 0 | AA21: =(SUMIFS([3]BASE_METAXREAL!$P$4:$P$22549,[3]BASE_METAXREAL!$W$4:$W$22549,B21,[3]BASE_METAXREAL!$K$4:$K$22549,"<>COMISSÕES E PREMIAÇÕES (Contratada)",[3]BASE_METAXREAL!$B$4:$B$22549,"<="&MONTH($A$13))/AA7)+ (SUMIFS([3]BASE_METAXREAL!$P$4:$P$22549,[3]BASE_METAXREAL!$W$4:$W$22549,B21,[3]BASE_METAXREAL!$K$4:$K$22549,"=COMISSÕES E PREMIAÇÕES (Contratada)",[3]BASE_METAXREAL!$B$4:$B$22549,"<="&MONTH($A$13))/AB7) -> #VALUE! | AB21: =(SUMIFS([3]BASE_METAXREAL!$O$4:$O$22549,[3]BASE_METAXREAL!$W$4:$W$22549,B21,[3]BASE_METAXREAL!$B$4:$B$22549,"<="&MONTH($A$13))/AB7) -> #VALUE! | AC21: =IFERROR((SUMIFS([3]BASE_METAXREAL!$P$4:$P$22549,[3]BASE_METAXREAL!$W$4:$W$22549,B21,[3]BASE_METAXREAL!$K$4:$K$22549,"<>COMISSÕES E PREMIAÇÕES (Contratada)",[3]BASE_METAXREAL!$B$4:$B$22549,MONTH($A$13))/AC7),0)+ IFERROR((SUMIFS([3]BASE_METAXREAL!$P$4:$P$22549,[3]BASE_METAXREAL!$W$4:$W$22549,B21,[3]BASE_METAXREAL!$K$4:$K$22549,"=COMISSÕES E PREMIAÇÕES (Contratada)",[3]BASE_METAXREAL!$B$4:$B$22549,MONTH($A$13))/AD7),0) -> 0 | AD21: =SUMIFS([3]BASE_METAXREAL!$O$4:$O$22549,[3]BASE_METAXREAL!$W$4:$W$22549,B21,[3]BASE_METAXREAL!$B$4:$B$22549,MONTH($A$13))/AD7 -> #VALUE!
B22: SP INT 6 | C22: =IFERROR(SUMIFS([3]BASE_METAXREAL!$P$4:$P$22549,[3]BASE_METAXREAL!$W$4:$W$22549,$B22,[3]BASE_METAXREAL!$B$4:$B$22549,C$13)/C8,0) -> 0 | D22: =IFERROR(SUMIFS([3]BASE_METAXREAL!$O$4:$O$22549,[3]BASE_METAXREAL!$W$4:$W$22549,$B22,[3]BASE_METAXREAL!$B$4:$B$22549,D$13)/D8,0) -> 0 | E22: =IFERROR(SUMIFS([3]BASE_METAXREAL!$P$4:$P$22549,[3]BASE_METAXREAL!$W$4:$W$22549,$B22,[3]BASE_METAXREAL!$B$4:$B$22549,E$13)/E8,0) -> 0 | F22: =IFERROR(SUMIFS([3]BASE_METAXREAL!$O$4:$O$22549,[3]BASE_METAXREAL!$W$4:$W$22549,$B22,[3]BASE_METAXREAL!$B$4:$B$22549,F$13)/F8,0) -> 0 | G22: =IFERROR(SUMIFS([3]BASE_METAXREAL!$P$4:$P$22549,[3]BASE_METAXREAL!$W$4:$W$22549,$B22,[3]BASE_METAXREAL!$B$4:$B$22549,G$13)/G8,0) -> 0 | H22: =IFERROR(SUMIFS([3]BASE_METAXREAL!$O$4:$O$22549,[3]BASE_METAXREAL!$W$4:$W$22549,$B22,[3]BASE_METAXREAL!$B$4:$B$22549,H$13)/H8,0) -> 0 | I22: =IFERROR(SUMIFS([3]BASE_METAXREAL!$P$4:$P$22549,[3]BASE_METAXREAL!$W$4:$W$22549,$B22,[3]BASE_METAXREAL!$B$4:$B$22549,I$13)/I8,0) -> 0 | J22: =IFERROR(SUMIFS([3]BASE_METAXREAL!$O$4:$O$22549,[3]BASE_METAXREAL!$W$4:$W$22549,$B22,[3]BASE_METAXREAL!$B$4:$B$22549,J$13)/J8,0) -> 0 | K22: =IFERROR(SUMIFS([3]BASE_METAXREAL!$P$4:$P$22549,[3]BASE_METAXREAL!$W$4:$W$22549,$B22,[3]BASE_METAXREAL!$B$4:$B$22549,K$13)/K8,0) -> 0 | L22: =IFERROR(SUMIFS([3]BASE_METAXREAL!$O$4:$O$22549,[3]BASE_METAXREAL!$W$4:$W$22549,$B22,[3]BASE_METAXREAL!$B$4:$B$22549,L$13)/L8,0) -> 0 | M22: =IFERROR(SUMIFS([3]BASE_METAXREAL!$P$4:$P$22549,[3]BASE_METAXREAL!$W$4:$W$22549,$B22,[3]BASE_METAXREAL!$B$4:$B$22549,M$13)/M8,0) -> 0 | N22: =IFERROR(SUMIFS([3]BASE_METAXREAL!$O$4:$O$22549,[3]BASE_METAXREAL!$W$4:$W$22549,$B22,[3]BASE_METAXREAL!$B$4:$B$22549,N$13)/N8,0) -> 0 | O22: =IFERROR(SUMIFS([3]BASE_METAXREAL!$P$4:$P$22549,[3]BASE_METAXREAL!$W$4:$W$22549,$B22,[3]BASE_METAXREAL!$B$4:$B$22549,O$13)/O8,0) -> 0 | P22: =IFERROR(SUMIFS([3]BASE_METAXREAL!$O$4:$O$22549,[3]BASE_METAXREAL!$W$4:$W$22549,$B22,[3]BASE_METAXREAL!$B$4:$B$22549,P$13)/P8,0) -> 0 | Q22: =IFERROR(SUMIFS([3]BASE_METAXREAL!$P$4:$P$22549,[3]BASE_METAXREAL!$W$4:$W$22549,$B22,[3]BASE_METAXREAL!$B$4:$B$22549,Q$13)/Q8,0) -> 0 | R22: =IFERROR(SUMIFS([3]BASE_METAXREAL!$O$4:$O$22549,[3]BASE_METAXREAL!$W$4:$W$22549,$B22,[3]BASE_METAXREAL!$B$4:$B$22549,R$13)/R8,0) -> 0 | S22: =IFERROR(SUMIFS([3]BASE_METAXREAL!$P$4:$P$22549,[3]BASE_METAXREAL!$W$4:$W$22549,$B22,[3]BASE_METAXREAL!$B$4:$B$22549,S$13)/S8,0) -> 0 | T22: =IFERROR(SUMIFS([3]BASE_METAXREAL!$O$4:$O$22549,[3]BASE_METAXREAL!$W$4:$W$22549,$B22,[3]BASE_METAXREAL!$B$4:$B$22549,T$13)/T8,0) -> 0 | U22: =IFERROR(SUMIFS([3]BASE_METAXREAL!$P$4:$P$22549,[3]BASE_METAXREAL!$W$4:$W$22549,$B22,[3]BASE_METAXREAL!$B$4:$B$22549,U$13)/U8,0) -> 0 | V22: =IFERROR(SUMIFS([3]BASE_METAXREAL!$O$4:$O$22549,[3]BASE_METAXREAL!$W$4:$W$22549,$B22,[3]BASE_METAXREAL!$B$4:$B$22549,V$13)/V8,0) -> 0 | W22: =IFERROR(SUMIFS([3]BASE_METAXREAL!$P$4:$P$22549,[3]BASE_METAXREAL!$W$4:$W$22549,$B22,[3]BASE_METAXREAL!$B$4:$B$22549,W$13)/W8,0) -> 0 | X22: =IFERROR(SUMIFS([3]BASE_METAXREAL!$O$4:$O$22549,[3]BASE_METAXREAL!$W$4:$W$22549,$B22,[3]BASE_METAXREAL!$B$4:$B$22549,X$13)/X8,0) -> 0 | Y22: =IFERROR(SUMIFS([3]BASE_METAXREAL!$P$4:$P$22549,[3]BASE_METAXREAL!$W$4:$W$22549,$B22,[3]BASE_METAXREAL!$B$4:$B$22549,Y$13)/Y8,0) -> 0 | Z22: =IFERROR(SUMIFS([3]BASE_METAXREAL!$O$4:$O$22549,[3]BASE_METAXREAL!$W$4:$W$22549,$B22,[3]BASE_METAXREAL!$B$4:$B$22549,Z$13)/Z8,0) -> 0 | AA22: =(SUMIFS([3]BASE_METAXREAL!$P$4:$P$22549,[3]BASE_METAXREAL!$W$4:$W$22549,B22,[3]BASE_METAXREAL!$K$4:$K$22549,"<>COMISSÕES E PREMIAÇÕES (Contratada)",[3]BASE_METAXREAL!$B$4:$B$22549,"<="&MONTH($A$13))/AA8)+ (SUMIFS([3]BASE_METAXREAL!$P$4:$P$22549,[3]BASE_METAXREAL!$W$4:$W$22549,B22,[3]BASE_METAXREAL!$K$4:$K$22549,"=COMISSÕES E PREMIAÇÕES (Contratada)",[3]BASE_METAXREAL!$B$4:$B$22549,"<="&MONTH($A$13))/AB8) -> #VALUE! | AB22: =(SUMIFS([3]BASE_METAXREAL!$O$4:$O$22549,[3]BASE_METAXREAL!$W$4:$W$22549,B22,[3]BASE_METAXREAL!$B$4:$B$22549,"<="&MONTH($A$13))/AB8) -> #VALUE! | AC22: =IFERROR((SUMIFS([3]BASE_METAXREAL!$P$4:$P$22549,[3]BASE_METAXREAL!$W$4:$W$22549,B22,[3]BASE_METAXREAL!$K$4:$K$22549,"<>COMISSÕES E PREMIAÇÕES (Contratada)",[3]BASE_METAXREAL!$B$4:$B$22549,MONTH($A$13))/AC8),0)+ IFERROR((SUMIFS([3]BASE_METAXREAL!$P$4:$P$22549,[3]BASE_METAXREAL!$W$4:$W$22549,B22,[3]BASE_METAXREAL!$K$4:$K$22549,"=COMISSÕES E PREMIAÇÕES (Contratada)",[3]BASE_METAXREAL!$B$4:$B$22549,MONTH($A$13))/AD8),0) -> 0 | AD22: =SUMIFS([3]BASE_METAXREAL!$O$4:$O$22549,[3]BASE_METAXREAL!$W$4:$W$22549,B22,[3]BASE_METAXREAL!$B$4:$B$22549,MONTH($A$13))/AD8 -> #VALUE!
B23: SENSIA CP | C23: =IFERROR(SUMIFS([3]BASE_METAXREAL!$P$4:$P$22549,[3]BASE_METAXREAL!$W$4:$W$22549,$B23,[3]BASE_METAXREAL!$B$4:$B$22549,C$13)/C9,0) -> 0 | D23: =IFERROR(SUMIFS([3]BASE_METAXREAL!$O$4:$O$22549,[3]BASE_METAXREAL!$W$4:$W$22549,$B23,[3]BASE_METAXREAL!$B$4:$B$22549,D$13)/D9,0) -> 0 | E23: =IFERROR(SUMIFS([3]BASE_METAXREAL!$P$4:$P$22549,[3]BASE_METAXREAL!$W$4:$W$22549,$B23,[3]BASE_METAXREAL!$B$4:$B$22549,E$13)/E9,0) -> 0 | F23: =IFERROR(SUMIFS([3]BASE_METAXREAL!$O$4:$O$22549,[3]BASE_METAXREAL!$W$4:$W$22549,$B23,[3]BASE_METAXREAL!$B$4:$B$22549,F$13)/F9,0) -> 0 | G23: =IFERROR(SUMIFS([3]BASE_METAXREAL!$P$4:$P$22549,[3]BASE_METAXREAL!$W$4:$W$22549,$B23,[3]BASE_METAXREAL!$B$4:$B$22549,G$13)/G9,0) -> 0 | H23: =IFERROR(SUMIFS([3]BASE_METAXREAL!$O$4:$O$22549,[3]BASE_METAXREAL!$W$4:$W$22549,$B23,[3]BASE_METAXREAL!$B$4:$B$22549,H$13)/H9,0) -> 0 | I23: =IFERROR(SUMIFS([3]BASE_METAXREAL!$P$4:$P$22549,[3]BASE_METAXREAL!$W$4:$W$22549,$B23,[3]BASE_METAXREAL!$B$4:$B$22549,I$13)/I9,0) -> 0 | J23: =IFERROR(SUMIFS([3]BASE_METAXREAL!$O$4:$O$22549,[3]BASE_METAXREAL!$W$4:$W$22549,$B23,[3]BASE_METAXREAL!$B$4:$B$22549,J$13)/J9,0) -> 0 | K23: =IFERROR(SUMIFS([3]BASE_METAXREAL!$P$4:$P$22549,[3]BASE_METAXREAL!$W$4:$W$22549,$B23,[3]BASE_METAXREAL!$B$4:$B$22549,K$13)/K9,0) -> 0 | L23: =IFERROR(SUMIFS([3]BASE_METAXREAL!$O$4:$O$22549,[3]BASE_METAXREAL!$W$4:$W$22549,$B23,[3]BASE_METAXREAL!$B$4:$B$22549,L$13)/L9,0) -> 0 | M23: =IFERROR(SUMIFS([3]BASE_METAXREAL!$P$4:$P$22549,[3]BASE_METAXREAL!$W$4:$W$22549,$B23,[3]BASE_METAXREAL!$B$4:$B$22549,M$13)/M9,0) -> 0 | N23: =IFERROR(SUMIFS([3]BASE_METAXREAL!$O$4:$O$22549,[3]BASE_METAXREAL!$W$4:$W$22549,$B23,[3]BASE_METAXREAL!$B$4:$B$22549,N$13)/N9,0) -> 0 | O23: =IFERROR(SUMIFS([3]BASE_METAXREAL!$P$4:$P$22549,[3]BASE_METAXREAL!$W$4:$W$22549,$B23,[3]BASE_METAXREAL!$B$4:$B$22549,O$13)/O9,0) -> 0 | P23: =IFERROR(SUMIFS([3]BASE_METAXREAL!$O$4:$O$22549,[3]BASE_METAXREAL!$W$4:$W$22549,$B23,[3]BASE_METAXREAL!$B$4:$B$22549,P$13)/P9,0) -> 0 | Q23: =IFERROR(SUMIFS([3]BASE_METAXREAL!$P$4:$P$22549,[3]BASE_METAXREAL!$W$4:$W$22549,$B23,[3]BASE_METAXREAL!$B$4:$B$22549,Q$13)/Q9,0) -> 0 | R23: =IFERROR(SUMIFS([3]BASE_METAXREAL!$O$4:$O$22549,[3]BASE_METAXREAL!$W$4:$W$22549,$B23,[3]BASE_METAXREAL!$B$4:$B$22549,R$13)/R9,0) -> 0 | S23: =IFERROR(SUMIFS([3]BASE_METAXREAL!$P$4:$P$22549,[3]BASE_METAXREAL!$W$4:$W$22549,$B23,[3]BASE_METAXREAL!$B$4:$B$22549,S$13)/S9,0) -> 0 | T23: =IFERROR(SUMIFS([3]BASE_METAXREAL!$O$4:$O$22549,[3]BASE_METAXREAL!$W$4:$W$22549,$B23,[3]BASE_METAXREAL!$B$4:$B$22549,T$13)/T9,0) -> 0 | U23: =IFERROR(SUMIFS([3]BASE_METAXREAL!$P$4:$P$22549,[3]BASE_METAXREAL!$W$4:$W$22549,$B23,[3]BASE_METAXREAL!$B$4:$B$22549,U$13)/U9,0) -> 0 | V23: =IFERROR(SUMIFS([3]BASE_METAXREAL!$O$4:$O$22549,[3]BASE_METAXREAL!$W$4:$W$22549,$B23,[3]BASE_METAXREAL!$B$4:$B$22549,V$13)/V9,0) -> 0 | W23: =IFERROR(SUMIFS([3]BASE_METAXREAL!$P$4:$P$22549,[3]BASE_METAXREAL!$W$4:$W$22549,$B23,[3]BASE_METAXREAL!$B$4:$B$22549,W$13)/W9,0) -> 0 | X23: =IFERROR(SUMIFS([3]BASE_METAXREAL!$O$4:$O$22549,[3]BASE_METAXREAL!$W$4:$W$22549,$B23,[3]BASE_METAXREAL!$B$4:$B$22549,X$13)/X9,0) -> 0 | Y23: =IFERROR(SUMIFS([3]BASE_METAXREAL!$P$4:$P$22549,[3]BASE_METAXREAL!$W$4:$W$22549,$B23,[3]BASE_METAXREAL!$B$4:$B$22549,Y$13)/Y9,0) -> 0 | Z23: =IFERROR(SUMIFS([3]BASE_METAXREAL!$O$4:$O$22549,[3]BASE_METAXREAL!$W$4:$W$22549,$B23,[3]BASE_METAXREAL!$B$4:$B$22549,Z$13)/Z9,0) -> 0 | AA23: =(SUMIFS([3]BASE_METAXREAL!$P$4:$P$22549,[3]BASE_METAXREAL!$W$4:$W$22549,B23,[3]BASE_METAXREAL!$K$4:$K$22549,"<>COMISSÕES E PREMIAÇÕES (Contratada)",[3]BASE_METAXREAL!$B$4:$B$22549,"<="&MONTH($A$13))/AA9)+ (SUMIFS([3]BASE_METAXREAL!$P$4:$P$22549,[3]BASE_METAXREAL!$W$4:$W$22549,B23,[3]BASE_METAXREAL!$K$4:$K$22549,"=COMISSÕES E PREMIAÇÕES (Contratada)",[3]BASE_METAXREAL!$B$4:$B$22549,"<="&MONTH($A$13))/AB9) -> #VALUE! | AB23: =(SUMIFS([3]BASE_METAXREAL!$O$4:$O$22549,[3]BASE_METAXREAL!$W$4:$W$22549,B23,[3]BASE_METAXREAL!$B$4:$B$22549,"<="&MONTH($A$13))/AB9) -> #VALUE! | AC23: =IFERROR((SUMIFS([3]BASE_METAXREAL!$P$4:$P$22549,[3]BASE_METAXREAL!$W$4:$W$22549,B23,[3]BASE_METAXREAL!$K$4:$K$22549,"<>COMISSÕES E PREMIAÇÕES (Contratada)",[3]BASE_METAXREAL!$B$4:$B$22549,MONTH($A$13))/AC9),0)+ IFERROR((SUMIFS([3]BASE_METAXREAL!$P$4:$P$22549,[3]BASE_METAXREAL!$W$4:$W$22549,B23,[3]BASE_METAXREAL!$K$4:$K$22549,"=COMISSÕES E PREMIAÇÕES (Contratada)",[3]BASE_METAXREAL!$B$4:$B$22549,MONTH($A$13))/AD9),0) -> 0 | AD23: =SUMIFS([3]BASE_METAXREAL!$O$4:$O$22549,[3]BASE_METAXREAL!$W$4:$W$22549,B23,[3]BASE_METAXREAL!$B$4:$B$22549,MONTH($A$13))/AD9 -> #VALUE!
B24: SENSIA RP | C24: =IFERROR(SUMIFS([3]BASE_METAXREAL!$P$4:$P$22549,[3]BASE_METAXREAL!$W$4:$W$22549,$B24,[3]BASE_METAXREAL!$B$4:$B$22549,C$13)/C10,0) -> 0 | D24: =IFERROR(SUMIFS([3]BASE_METAXREAL!$O$4:$O$22549,[3]BASE_METAXREAL!$W$4:$W$22549,$B24,[3]BASE_METAXREAL!$B$4:$B$22549,D$13)/D10,0) -> 0 | E24: =IFERROR(SUMIFS([3]BASE_METAXREAL!$P$4:$P$22549,[3]BASE_METAXREAL!$W$4:$W$22549,$B24,[3]BASE_METAXREAL!$B$4:$B$22549,E$13)/E10,0) -> 0 | F24: =IFERROR(SUMIFS([3]BASE_METAXREAL!$O$4:$O$22549,[3]BASE_METAXREAL!$W$4:$W$22549,$B24,[3]BASE_METAXREAL!$B$4:$B$22549,F$13)/F10,0) -> 0 | G24: =IFERROR(SUMIFS([3]BASE_METAXREAL!$P$4:$P$22549,[3]BASE_METAXREAL!$W$4:$W$22549,$B24,[3]BASE_METAXREAL!$B$4:$B$22549,G$13)/G10,0) -> 0 | H24: =IFERROR(SUMIFS([3]BASE_METAXREAL!$O$4:$O$22549,[3]BASE_METAXREAL!$W$4:$W$22549,$B24,[3]BASE_METAXREAL!$B$4:$B$22549,H$13)/H10,0) -> 0 | I24: =IFERROR(SUMIFS([3]BASE_METAXREAL!$P$4:$P$22549,[3]BASE_METAXREAL!$W$4:$W$22549,$B24,[3]BASE_METAXREAL!$B$4:$B$22549,I$13)/I10,0) -> 0 | J24: =IFERROR(SUMIFS([3]BASE_METAXREAL!$O$4:$O$22549,[3]BASE_METAXREAL!$W$4:$W$22549,$B24,[3]BASE_METAXREAL!$B$4:$B$22549,J$13)/J10,0) -> 0 | K24: =IFERROR(SUMIFS([3]BASE_METAXREAL!$P$4:$P$22549,[3]BASE_METAXREAL!$W$4:$W$22549,$B24,[3]BASE_METAXREAL!$B$4:$B$22549,K$13)/K10,0) -> 0 | L24: =IFERROR(SUMIFS([3]BASE_METAXREAL!$O$4:$O$22549,[3]BASE_METAXREAL!$W$4:$W$22549,$B24,[3]BASE_METAXREAL!$B$4:$B$22549,L$13)/L10,0) -> 0 | M24: =IFERROR(SUMIFS([3]BASE_METAXREAL!$P$4:$P$22549,[3]BASE_METAXREAL!$W$4:$W$22549,$B24,[3]BASE_METAXREAL!$B$4:$B$22549,M$13)/M10,0) -> 0 | N24: =IFERROR(SUMIFS([3]BASE_METAXREAL!$O$4:$O$22549,[3]BASE_METAXREAL!$W$4:$W$22549,$B24,[3]BASE_METAXREAL!$B$4:$B$22549,N$13)/N10,0) -> 0 | O24: =IFERROR(SUMIFS([3]BASE_METAXREAL!$P$4:$P$22549,[3]BASE_METAXREAL!$W$4:$W$22549,$B24,[3]BASE_METAXREAL!$B$4:$B$22549,O$13)/O10,0) -> 0 | P24: =IFERROR(SUMIFS([3]BASE_METAXREAL!$O$4:$O$22549,[3]BASE_METAXREAL!$W$4:$W$22549,$B24,[3]BASE_METAXREAL!$B$4:$B$22549,P$13)/P10,0) -> 0 | Q24: =IFERROR(SUMIFS([3]BASE_METAXREAL!$P$4:$P$22549,[3]BASE_METAXREAL!$W$4:$W$22549,$B24,[3]BASE_METAXREAL!$B$4:$B$22549,Q$13)/Q10,0) -> 0 | R24: =IFERROR(SUMIFS([3]BASE_METAXREAL!$O$4:$O$22549,[3]BASE_METAXREAL!$W$4:$W$22549,$B24,[3]BASE_METAXREAL!$B$4:$B$22549,R$13)/R10,0) -> 0 | S24: =IFERROR(SUMIFS([3]BASE_METAXREAL!$P$4:$P$22549,[3]BASE_METAXREAL!$W$4:$W$22549,$B24,[3]BASE_METAXREAL!$B$4:$B$22549,S$13)/S10,0) -> 0 | T24: =IFERROR(SUMIFS([3]BASE_METAXREAL!$O$4:$O$22549,[3]BASE_METAXREAL!$W$4:$W$22549,$B24,[3]BASE_METAXREAL!$B$4:$B$22549,T$13)/T10,0) -> 0 | U24: =IFERROR(SUMIFS([3]BASE_METAXREAL!$P$4:$P$22549,[3]BASE_METAXREAL!$W$4:$W$22549,$B24,[3]BASE_METAXREAL!$B$4:$B$22549,U$13)/U10,0) -> 0 | V24: =IFERROR(SUMIFS([3]BASE_METAXREAL!$O$4:$O$22549,[3]BASE_METAXREAL!$W$4:$W$22549,$B24,[3]BASE_METAXREAL!$B$4:$B$22549,V$13)/V10,0) -> 0 | W24: =IFERROR(SUMIFS([3]BASE_METAXREAL!$P$4:$P$22549,[3]BASE_METAXREAL!$W$4:$W$22549,$B24,[3]BASE_METAXREAL!$B$4:$B$22549,W$13)/W10,0) -> 0 | X24: =IFERROR(SUMIFS([3]BASE_METAXREAL!$O$4:$O$22549,[3]BASE_METAXREAL!$W$4:$W$22549,$B24,[3]BASE_METAXREAL!$B$4:$B$22549,X$13)/X10,0) -> 0 | Y24: =IFERROR(SUMIFS([3]BASE_METAXREAL!$P$4:$P$22549,[3]BASE_METAXREAL!$W$4:$W$22549,$B24,[3]BASE_METAXREAL!$B$4:$B$22549,Y$13)/Y10,0) -> 0 | Z24: =IFERROR(SUMIFS([3]BASE_METAXREAL!$O$4:$O$22549,[3]BASE_METAXREAL!$W$4:$W$22549,$B24,[3]BASE_METAXREAL!$B$4:$B$22549,Z$13)/Z10,0) -> 0 | AA24: =(SUMIFS([3]BASE_METAXREAL!$P$4:$P$22549,[3]BASE_METAXREAL!$W$4:$W$22549,B24,[3]BASE_METAXREAL!$K$4:$K$22549,"<>COMISSÕES E PREMIAÇÕES (Contratada)",[3]BASE_METAXREAL!$B$4:$B$22549,"<="&MONTH($A$13))/AA10)+ (SUMIFS([3]BASE_METAXREAL!$P$4:$P$22549,[3]BASE_METAXREAL!$W$4:$W$22549,B24,[3]BASE_METAXREAL!$K$4:$K$22549,"=COMISSÕES E PREMIAÇÕES (Contratada)",[3]BASE_METAXREAL!$B$4:$B$22549,"<="&MONTH($A$13))/AB10) -> #VALUE! | AB24: =(SUMIFS([3]BASE_METAXREAL!$O$4:$O$22549,[3]BASE_METAXREAL!$W$4:$W$22549,B24,[3]BASE_METAXREAL!$B$4:$B$22549,"<="&MONTH($A$13))/AB10) -> #VALUE! | AC24: =IFERROR((SUMIFS([3]BASE_METAXREAL!$P$4:$P$22549,[3]BASE_METAXREAL!$W$4:$W$22549,B24,[3]BASE_METAXREAL!$K$4:$K$22549,"<>COMISSÕES E PREMIAÇÕES (Contratada)",[3]BASE_METAXREAL!$B$4:$B$22549,MONTH($A$13))/AC10),0)+ IFERROR((SUMIFS([3]BASE_METAXREAL!$P$4:$P$22549,[3]BASE_METAXREAL!$W$4:$W$22549,B24,[3]BASE_METAXREAL!$K$4:$K$22549,"=COMISSÕES E PREMIAÇÕES (Contratada)",[3]BASE_METAXREAL!$B$4:$B$22549,MONTH($A$13))/AD10),0) -> 0 | AD24: =SUMIFS([3]BASE_METAXREAL!$O$4:$O$22549,[3]BASE_METAXREAL!$W$4:$W$22549,B24,[3]BASE_METAXREAL!$B$4:$B$22549,MONTH($A$13))/AD10 -> #VALUE!
